Workbook

Sheet Resumen Ejecutivo
E2: =+'Base valores'!AB2 -> COMISIÓN FEDERAL DE ELECTRICIDAD | O2: Rev
E3: =+'Base valores'!AB3 -> COORDINACIÓN DE PROYECTOS DE ENERGÍAS LIMPIAS | O3: 3
E4: =+'Base valores'!AB4 -> GERENCIA DE CONSTRUCCIÓN | O4: =TODAY() -> 46322
E5: ESTADO DE TRÁMITES Y PERMISOS DE PROYECTOS MIXTOS, SEGUNDA RONDA
C7: Socio | D7: Proyecto | E7: Municipio | F7: Entidad | G7: Tipo | H7: Capacidad | I7: Fecha de inicio de inversión | J7: COD | K7: Avance en trámites y/o permisos | O7: Grupo de atención
K8: Parque | L8: LT | M8: Global
B9: 1 | C9: =+'Base valores'!C11 -> Invenergy Solar Development Mexico S de RL de CV | D9: =+'Base valores'!D11 -> Bura Energy Center II | E9: =+'Base valores'!E11 -> Tecate | F9: =+'Base valores'!F11 -> Baja California | G9: =+'Base valores'!G11 -> Fotovoltaica | H9: =+'Base valores'!H11 -> 38 | I9: =+'Base valores'!I11 -> - | J9: =+'Base valores'!J11 -> - | K9: =+'Base valores'!AD11 -> 0 | L9: =+'Base valores'!AE11 -> 0 | M9: =+'Base valores'!AG11 -> 0 | O9: C | R9: A | S9: =COUNTIFS($O$9:$O$72,R9) -> 0
B10: 2 | C10: =+'Base valores'!C12 -> Energica Tenedora de Mexico SA de CV | D10: =+'Base valores'!D12 -> CFE Cerro Prieto | E10: =+'Base valores'!E12 -> Mexicali | F10: =+'Base valores'!F12 -> Baja California | G10: =+'Base valores'!G12 -> Fotovoltaica | H10: =+'Base valores'!H12 -> 215 | I10: =+'Base valores'!I12 -> - | J10: =+'Base valores'!J12 -> - | K10: =+'Base valores'!AD12 -> 0 | L10: =+'Base valores'!AE12 -> 0 | M10: =+'Base valores'!AG12 -> 0 | O10: C | R10: B | S10: =COUNTIFS($O$9:$O$72,R10) -> 0
B11: 3 | C11: =+'Base valores'!C13 -> Energica Tenedora de Mexico SA de CV | D11: =+'Base valores'!D13 -> ICA Punta Colonet | E11: =+'Base valores'!E13 -> Ensenada | F11: =+'Base valores'!F13 -> Baja California | G11: =+'Base valores'!G13 -> Fotovoltaica | H11: =+'Base valores'!H13 -> 120 | I11: =+'Base valores'!I13 -> - | J11: =+'Base valores'!J13 -> - | K11: =+'Base valores'!AD13 -> 0 | L11: =+'Base valores'!AE13 -> 0 | M11: =+'Base valores'!AG13 -> 0 | O11: C | R11: C | S11: =COUNTIFS($O$9:$O$72,R11) -> 64
B12: 4 | C12: =+'Base valores'!C14 -> Energica Tenedora de Mexico SA de CV | D12: =+'Base valores'!D14 -> ICA San Luis Rio Colorado | E12: =+'Base valores'!E14 -> San Luis Río Colorado | F12: =+'Base valores'!F14 -> Sonora | G12: =+'Base valores'!G14 -> Fotovoltaica | H12: =+'Base valores'!H14 -> 100 | I12: =+'Base valores'!I14 -> - | J12: =+'Base valores'!J14 -> - | K12: =+'Base valores'!AD14 -> 0 | L12: =+'Base valores'!AE14 -> 0 | M12: =+'Base valores'!AG14 -> 0 | O12: C
B13: 5 | C13: =+'Base valores'!C15 -> PYE Electrificaciones S de RL de CV | D13: =+'Base valores'!D15 -> Planta Solar Fotovoltaica Mesa Andrade I | E13: =+'Base valores'!E15 -> Mexicali | F13: =+'Base valores'!F15 -> Baja California | G13: =+'Base valores'!G15 -> Fotovoltaica | H13: =+'Base valores'!H15 -> 132 | I13: =+'Base valores'!I15 -> - | J13: =+'Base valores'!J15 -> - | K13: =+'Base valores'!AD15 -> 0 | L13: =+'Base valores'!AE15 -> 0 | M13: =+'Base valores'!AG15 -> 0 | O13: C
B14: 6 | C14: =+'Base valores'!C16 -> Energia Firme Sigma S A P I de CV | D14: =+'Base valores'!D16 -> San Felipe Solar | E14: =+'Base valores'!E16 -> San Felipe | F14: =+'Base valores'!F16 -> Baja California | G14: =+'Base valores'!G16 -> Fotovoltaica | H14: =+'Base valores'!H16 -> 100 | I14: =+'Base valores'!I16 -> - | J14: =+'Base valores'!J16 -> - | K14: =+'Base valores'!AD16 -> 0 | L14: =+'Base valores'!AE16 -> 0 | M14: =+'Base valores'!AG16 -> 0 | O14: C
B15: 7 | C15: =+'Base valores'!C17 -> Electrica Aselco SA de CV | D15: =+'Base valores'!D17 -> Insurgentes | E15: =+'Base valores'!E17 -> Comondú | F15: =+'Base valores'!F17 -> Baja California Sur | G15: =+'Base valores'!G17 -> Fotovoltaica | H15: =+'Base valores'!H17 -> 36.58 | I15: =+'Base valores'!I17 -> - | J15: =+'Base valores'!J17 -> - | K15: =+'Base valores'!AD17 -> 0 | L15: =+'Base valores'!AE17 -> 0 | M15: =+'Base valores'!AG17 -> 0 | O15: C
B16: 8 | C16: =+'Base valores'!C18 -> Innovaciones Energeticas Inner SA de CV | D16: =+'Base valores'!D18 -> Loreto | E16: =+'Base valores'!E18 -> Loreto | F16: =+'Base valores'!F18 -> Baja California Sur | G16: =+'Base valores'!G18 -> Fotovoltaica | H16: =+'Base valores'!H18 -> 50 | I16: =+'Base valores'!I18 -> - | J16: =+'Base valores'!J18 -> - | K16: =+'Base valores'!AD18 -> 0 | L16: =+'Base valores'!AE18 -> 0 | M16: =+'Base valores'!AG18 -> 0 | O16: C
B17: 9 | C17: =+'Base valores'!C19 -> Invenergy Solar Development Mexico S de RL de CV | D17: =+'Base valores'!D19 -> Loreto Energy Center | E17: =+'Base valores'!E19 -> Loreto | F17: =+'Base valores'!F19 -> Baja California Sur | G17: =+'Base valores'!G19 -> Fotovoltaica | H17: =+'Base valores'!H19 -> 30 | I17: =+'Base valores'!I19 -> - | J17: =+'Base valores'!J19 -> - | K17: =+'Base valores'!AD19 -> 0 | L17: =+'Base valores'!AE19 -> 0 | M17: =+'Base valores'!AG19 -> 0 | O17: C
B18: 10 | C18: =+'Base valores'!C20 -> Soluciones Energeticas Para La Transformacion BCS S A P I de CV | D18: =+'Base valores'!D20 -> Proyecto Solar San Jose Del Cabo | E18: =+'Base valores'!E20 -> Los Cabos | F18: =+'Base valores'!F20 -> Baja California Sur | G18: =+'Base valores'!G20 -> Fotovoltaica | H18: =+'Base valores'!H20 -> 30 | I18: =+'Base valores'!I20 -> - | J18: =+'Base valores'!J20 -> - | K18: =+'Base valores'!AD20 -> 0 | L18: =+'Base valores'!AE20 -> 0 | M18: =+'Base valores'!AG20 -> 0 | O18: C
B19: 11 | C19: =+'Base valores'!C21 -> BU ST Services S de RL de CV | D19: =+'Base valores'!D21 -> Santiago Solar | E19: =+'Base valores'!E21 -> Los Cabos | F19: =+'Base valores'!F21 -> Baja California Sur | G19: =+'Base valores'!G21 -> Fotovoltaica | H19: =+'Base valores'!H21 -> 40 | I19: =+'Base valores'!I21 -> - | J19: =+'Base valores'!J21 -> - | K19: =+'Base valores'!AD21 -> 0 | L19: =+'Base valores'!AE21 -> 0 | M19: =+'Base valores'!AG21 -> 0 | O19: C
B20: 12 | C20: =+'Base valores'!C22 -> Atlacomulco Solar Fotovoltaica SA de CV | D20: =+'Base valores'!D22 -> Atlacomulco | E20: =+'Base valores'!E22 -> Jocotitlán | F20: =+'Base valores'!F22 -> Estado de México | G20: =+'Base valores'!G22 -> Fotovoltaica | H20: =+'Base valores'!H22 -> 100 | I20: =+'Base valores'!I22 -> - | J20: =+'Base valores'!J22 -> - | K20: =+'Base valores'!AD22 -> 0 | L20: =+'Base valores'!AE22 -> 0 | M20: =+'Base valores'!AG22 -> 0 | O20: C
B21: 13 | C21: =+'Base valores'!C23 -> Atlacomulco Solar SA de CV | D21: =+'Base valores'!D23 -> Atlacomulco Solar | E21: =+'Base valores'!E23 -> Almoloya de Juárez | F21: =+'Base valores'!F23 -> Estado de México | G21: =+'Base valores'!G23 -> Fotovoltaica | H21: =+'Base valores'!H23 -> 90 | I21: =+'Base valores'!I23 -> - | J21: =+'Base valores'!J23 -> - | K21: =+'Base valores'!AD23 -> 0 | L21: =+'Base valores'!AE23 -> 0 | M21: =+'Base valores'!AG23 -> 0 | O21: C
B22: 14 | C22: =+'Base valores'!C24 -> Ruenergy Projects Mexico SA de CV | D22: =+'Base valores'!D24 -> Central FV Ixtapan | E22: =+'Base valores'!E24 -> Ixtapan de la Sal | F22: =+'Base valores'!F24 -> Estado de México | G22: =+'Base valores'!G24 -> Fotovoltaica | H22: =+'Base valores'!H24 -> 59.7 | I22: =+'Base valores'!I24 -> - | J22: =+'Base valores'!J24 -> - | K22: =+'Base valores'!AD24 -> 0 | L22: =+'Base valores'!AE24 -> 0 | M22: =+'Base valores'!AG24 -> 0 | O22: C
B23: 15 | C23: =+'Base valores'!C25 -> Terralia Energia y Campo SA de CV | D23: =+'Base valores'!D25 -> Manzano | E23: =+'Base valores'!E25 -> Contepec | F23: =+'Base valores'!F25 -> Michoacán | G23: =+'Base valores'!G25 -> Fotovoltaica | H23: =+'Base valores'!H25 -> 46.21 | I23: =+'Base valores'!I25 -> - | J23: =+'Base valores'!J25 -> - | K23: =+'Base valores'!AD25 -> 0 | L23: =+'Base valores'!AE25 -> 0 | M23: =+'Base valores'!AG25 -> 0 | O23: C
... B72: 64 | C72: =+'Base valores'!C74 -> PV El Tintillo Solar SG S de RL de CV | D72: =+'Base valores'!D74 -> PV Tecamachalco Solar | E72: =+'Base valores'!E74 -> Tecamachalco | F72: =+'Base valores'!F74 -> Puebla | G72: =+'Base valores'!G74 -> Fotovoltaica | H72: =+'Base valores'!H74 -> 36 | I72: =+'Base valores'!I74 -> - | J72: =+'Base valores'!J74 -> - | K72: =+'Base valores'!AD74 -> 0 | L72: =+'Base valores'!AE74 -> 0 | M72: =+'Base valores'!AG74 -> 0 | O72: C
F74: AVANCE GLOBAL | K74: =AVERAGE(K9:K72) -> 0 | L74: =AVERAGE(L9:L72) -> 0 | M74: =AVERAGE(M9:M72) -> 0
C95: NOTAS Y SIMBOLOGÍA
C96: Premisis y supuestos de análisis | D96: Se analizan por separado el Parque y la LT | E96: Trámites y/o Permisos que se incluyen en el presenta análisis | F96: Tenencia de la tierra (pondera 10%)
D97: Parque (pondera 80%) | F97: Estudios de Interconexión (pondera 10%)
D98: LT (pondera 20%) | F98: Manifestación de Impacto Ambientyal (ponedra 20%)
C99: Código de colores | D99: Verde: De un 85.00% a un 100% | F99: Estudio Técnico Justificativo (pondera 10%)
D100: Amarillo: De un 75.00% a un 84.99% | F100: Manifestación de Impacto Social (pondera 20%)
D101: Rojo: Debajo de 75% | F101: Consulta Indígena (pondera 10%)
C102: (*) | D102: Proyecto en segunda ronda de Proyectos Mixtos | F102: Instituto Nacional de Antropología e Historia (pondera 5%)
C103: (**) | D103: Proyecto que no puede ser ingresado al SEN sin que entren obras de refuerzo por un tercero; según CENACE | F103: Comisión Nacional del Agua (pondera 5%)
F104: Petroleos Mexicanos (5%)
F105: Asgencia Federal de Aviación Civil (pondera 5%)
K109: 1 | L109: 1 | M109: 1
K110: 0 | L110: 0 | M110: 0

Sheet Proyectos ok
E2: =+'Base valores'!AB2 -> COMISIÓN FEDERAL DE ELECTRICIDAD | V2: Rev
E3: =+'Base valores'!AB3 -> COORDINACIÓN DE PROYECTOS DE ENERGÍAS LIMPIAS | V3: 4
E4: =+'Base valores'!AB4 -> GERENCIA DE CONSTRUCCIÓN | V4: =TODAY() -> 46322
E5: ESTADO DE TRÁMITES Y PERMISOS DE PROYECTOS MIXTOS, PRIMERA RONDA
C7: Socio | D7: Proyecto | E7: Municipio | F7: Estado | G7: Tipo | H7: Capacidad | I7: Fecha de Inicio de inversión | J7: COD | K7: Trámites y Permisos del Parque | V7: Grupo de Atención
K8: Derechos inmobiliarios | L8: Estudios Interconexión | M8: MIA / DTU | N8: ETJ | O8: MISSE / EVIS | P8: Consulta Indígena | Q8: PEMEX | R8: INAH | S8: CONAGUA | T8: AFAC
B9: 1 | Y9: A | Z9: ='Resumen Ejecutivo'!S9 -> 0
B10: 2 | Y10: B | Z10: ='Resumen Ejecutivo'!S10 -> 0
B11: 3 | Y11: C | Z11: ='Resumen Ejecutivo'!S11 -> 64
B12: 4
B13: 14
B14: 15
B15: 16
B16: 17
B17: 18
B18: 19
C20: NOTAS Y SIMBOLOGÍA
C21: Premisis y supuestos de análisis | D21: Se analizan por separado el Parque y la LT | E21: Trámites y/o Permisos que se incluyen en el presenta análisis | F21: Tenencia de la tierra (pondera 10%) | K21: Código de colores (CELDAS) | L21: Gris | M21: Pendiente: Trámite no iniciado o sin información por parte del socio.
D22: Parque (pondera 80%) | F22: Estudios de Interconexión (pondera 10%) | L22: Rojo | M22: En elaboración: El socio se encuentra integrando documentación y preparando el ingreso.
D23: LT (pondera 20%) | F23: Manifestación de Impacto Ambientyal (pondera 20%) | L23: Amarillo | M23: En evaluación: Trámite ingresado ante la autoridad y en proceso de revisión.
C24: Código de colores (Grupo) | D24: Verde: De un 85.00% a un 100% | F24: Estudio Técnico Justificativo (pondera 10%) | L24: Azul | M24: Requerimiento: La autoridad solicitó información adicional, aclaraciones, precisiones o se requiere una actualización derivada de cambios del socio.
D25: Amarillo: De un 75.00% a un 84.99% | F25: Manifestación de Impacto Social (pondera 20%) | L25: Azul | M25: En actualización: La autoridad solicitó información adicional, aclaraciones, precisiones o se requiere una actualización derivada de cambios del socio.
D26: Rojo: Debajo de 75% | F26: Consulta Indígena (pondera 10%) | L26: Naranja | M26: En dictaminación: La información requerida fue entregada y el trámite se encuentra en revisión final para emisión del fallo.
C27: (*) | D27: Proyecto en segunda ronda de Proyectos Mixtos | F27: Instituto Nacional de Antropología e Historia (pondera 5%) | L27: Verde claro | M27: Liberado: Autorización o fallo favorable emitido por la autoridad.
C28: (**) | D28: Proyecto que no puede ser ingresado al SEN sin que entren obras de refuerzo por un tercero; según CENACE | F28: Comisión Nacional del Agua (pondera 5%) | L28: Verde claro | M28: N/A: Trámite no requerido o no aplicable.
F29: Petroleos Mexicanos (5%)
F30: Asgencia Federal de Aviación Civil (pondera 5%)

Sheet Base valores
AB2: COMISIÓN FEDERAL DE ELECTRICIDAD | AD2: Rev 4 | AG2: =TODAY() -> 46322
AB3: COORDINACIÓN DE PROYECTOS DE ENERGÍAS LIMPIAS
AB4: GERENCIA DE CONSTRUCCIÓN
G5: ESTADO DE TRÁMITES Y PERMISOS DE PROYECTOS MIXTOS, SEGUNDA RONDA
B8: No. | C8: Socio | D8: Proyecto | E8: Municipio | F8: Entidad | G8: Tecnología | H8: Capacidad | I8: Fecha de Incio de invesión | J8: COD | K8: Derechos Inmobiliarios | M8: Estudios de interconexión | N8: Ambientales | R8: Social | U8: Dependencias | AD8: Avance Tratimtes Parque | AE8: Avance Tramites Línea | AG8: Avance Trámites Proyecto
N9: MIA - DTU | P9: ETJ | R9: MISSE (EvIS) | T9: Consulta Indígena | U9: INAH | W9: PEMEX | Y9: CONAGUA | AA9: AFAC
K10: Parque | L10: LT | N10: Parque | O10: LT | P10: Parque | Q10: LT | R10: Parque | S10: LT | U10: Parque | V10: LT | W10: Parque | X10: LT | Y10: Parque | Z10: LT | AA10: Parque | AB10: LT
B11: 1 | C11: Invenergy Solar Development Mexico S de RL de CV | D11: Bura Energy Center II | E11: Tecate | F11: Baja California | G11: Fotovoltaica | H11: 38 | I11: - | J11: - | K11: 0 | L11: 0 | M11: 0 | N11: 0 | O11: 0 | P11: 0 | Q11: 0 | R11: 0 | S11: 0 | T11: 0 | U11: 0 | V11: 0 | W11: 0 | X11: 0 | Y11: 0 | Z11: 0 | AA11: 0 | AB11: 0 | AD11: =+(K11*$K$76)+(M11*$M$76)+(N11*$N$76)+(P11*$P$76)+(R11*$R$76)+(T11*$T$76)+(U11*$U$76)+(W11*$W$76)+(Y11*$Y$76)+(AA11*$AA$76) -> 0 | AE11: =+(L11*$K$76)+(M11*$M$76)+(O11*$N$76)+(Q11*$P$76)+(S11*$R$76)+(T11*$T$76)+(V11*$U$76)+(X11*$W$76)+(Z11*$Y$76)+(AB11*$AA$76) -> 0 | AG11: =+(AD11*$AD$76)+(AE11*$AE$76) -> 0
B12: 2 | C12: Energica Tenedora de Mexico SA de CV | D12: CFE Cerro Prieto | E12: Mexicali | F12: Baja California | G12: Fotovoltaica | H12: 215 | I12: - | J12: - | K12: 0 | L12: 0 | M12: 0 | N12: 0 | O12: 0 | P12: 0 | Q12: 0 | R12: 0 | S12: 0 | T12: 0 | U12: 0 | V12: 0 | W12: 0 | X12: 0 | Y12: 0 | Z12: 0 | AA12: 0 | AB12: 0 | AD12: =+(K12*$K$76)+(M12*$M$76)+(N12*$N$76)+(P12*$P$76)+(R12*$R$76)+(T12*$T$76)+(U12*$U$76)+(W12*$W$76)+(Y12*$Y$76)+(AA12*$AA$76) -> 0 | AE12: =+(L12*$K$76)+(M12*$M$76)+(O12*$N$76)+(Q12*$P$76)+(S12*$R$76)+(T12*$T$76)+(V12*$U$76)+(X12*$W$76)+(Z12*$Y$76)+(AB12*$AA$76) -> 0 | AG12: =+(AD12*$AD$76)+(AE12*$AE$76) -> 0
B13: 3 | C13: Energica Tenedora de Mexico SA de CV | D13: ICA Punta Colonet | E13: Ensenada | F13: Baja California | G13: Fotovoltaica | H13: 120 | I13: - | J13: - | K13: 0 | L13: 0 | M13: 0 | N13: 0 | O13: 0 | P13: 0 | Q13: 0 | R13: 0 | S13: 0 | T13: 0 | U13: 0 | V13: 0 | W13: 0 | X13: 0 | Y13: 0 | Z13: 0 | AA13: 0 | AB13: 0 | AD13: =+(K13*$K$76)+(M13*$M$76)+(N13*$N$76)+(P13*$P$76)+(R13*$R$76)+(T13*$T$76)+(U13*$U$76)+(W13*$W$76)+(Y13*$Y$76)+(AA13*$AA$76) -> 0 | AE13: =+(L13*$K$76)+(M13*$M$76)+(O13*$N$76)+(Q13*$P$76)+(S13*$R$76)+(T13*$T$76)+(V13*$U$76)+(X13*$W$76)+(Z13*$Y$76)+(AB13*$AA$76) -> 0 | AG13: =+(AD13*$AD$76)+(AE13*$AE$76) -> 0
B14: 4 | C14: Energica Tenedora de Mexico SA de CV | D14: ICA San Luis Rio Colorado | E14: San Luis Río Colorado | F14: Sonora | G14: Fotovoltaica | H14: 100 | I14: - | J14: - | K14: 0 | L14: 0 | M14: 0 | N14: 0 | O14: 0 | P14: 0 | Q14: 0 | R14: 0 | S14: 0 | T14: 0 | U14: 0 | V14: 0 | W14: 0 | X14: 0 | Y14: 0 | Z14: 0 | AA14: 0 | AB14: 0 | AD14: =+(K14*$K$76)+(M14*$M$76)+(N14*$N$76)+(P14*$P$76)+(R14*$R$76)+(T14*$T$76)+(U14*$U$76)+(W14*$W$76)+(Y14*$Y$76)+(AA14*$AA$76) -> 0 | AE14: =+(L14*$K$76)+(M14*$M$76)+(O14*$N$76)+(Q14*$P$76)+(S14*$R$76)+(T14*$T$76)+(V14*$U$76)+(X14*$W$76)+(Z14*$Y$76)+(AB14*$AA$76) -> 0 | AG14: =+(AD14*$AD$76)+(AE14*$AE$76) -> 0
B15: 5 | C15: PYE Electrificaciones S de RL de CV | D15: Planta Solar Fotovoltaica Mesa Andrade I | E15: Mexicali | F15: Baja California | G15: Fotovoltaica | H15: 132 | I15: - | J15: - | K15: 0 | L15: 0 | M15: 0 | N15: 0 | O15: 0 | P15: 0 | Q15: 0 | R15: 0 | S15: 0 | T15: 0 | U15: 0 | V15: 0 | W15: 0 | X15: 0 | Y15: 0 | Z15: 0 | AA15: 0 | AB15: 0 | AD15: =+(K15*$K$76)+(M15*$M$76)+(N15*$N$76)+(P15*$P$76)+(R15*$R$76)+(T15*$T$76)+(U15*$U$76)+(W15*$W$76)+(Y15*$Y$76)+(AA15*$AA$76) -> 0 | AE15: =+(L15*$K$76)+(M15*$M$76)+(O15*$N$76)+(Q15*$P$76)+(S15*$R$76)+(T15*$T$76)+(V15*$U$76)+(X15*$W$76)+(Z15*$Y$76)+(AB15*$AA$76) -> 0 | AG15: =+(AD15*$AD$76)+(AE15*$AE$76) -> 0
B16: 6 | C16: Energia Firme Sigma S A P I de CV | D16: San Felipe Solar | E16: San Felipe | F16: Baja California | G16: Fotovoltaica | H16: 100 | I16: - | J16: - | K16: 0 | L16: 0 | M16: 0 | N16: 0 | O16: 0 | P16: 0 | Q16: 0 | R16: 0 | S16: 0 | T16: 0 | U16: 0 | V16: 0 | W16: 0 | X16: 0 | Y16: 0 | Z16: 0 | AA16: 0 | AB16: 0 | AD16: =+(K16*$K$76)+(M16*$M$76)+(N16*$N$76)+(P16*$P$76)+(R16*$R$76)+(T16*$T$76)+(U16*$U$76)+(W16*$W$76)+(Y16*$Y$76)+(AA16*$AA$76) -> 0 | AE16: =+(L16*$K$76)+(M16*$M$76)+(O16*$N$76)+(Q16*$P$76)+(S16*$R$76)+(T16*$T$76)+(V16*$U$76)+(X16*$W$76)+(Z16*$Y$76)+(AB16*$AA$76) -> 0 | AG16: =+(AD16*$AD$76)+(AE16*$AE$76) -> 0
B17: 7 | C17: Electrica Aselco SA de CV | D17: Insurgentes | E17: Comondú | F17: Baja California Sur | G17: Fotovoltaica | H17: 36.58 | I17: - | J17: - | K17: 0 | L17: 0 | M17: 0 | N17: 0 | O17: 0 | P17: 0 | Q17: 0 | R17: 0 | S17: 0 | T17: 0 | U17: 0 | V17: 0 | W17: 0 | X17: 0 | Y17: 0 | Z17: 0 | AA17: 0 | AB17: 0 | AD17: =+(K17*$K$76)+(M17*$M$76)+(N17*$N$76)+(P17*$P$76)+(R17*$R$76)+(T17*$T$76)+(U17*$U$76)+(W17*$W$76)+(Y17*$Y$76)+(AA17*$AA$76) -> 0 | AE17: =+(L17*$K$76)+(M17*$M$76)+(O17*$N$76)+(Q17*$P$76)+(S17*$R$76)+(T17*$T$76)+(V17*$U$76)+(X17*$W$76)+(Z17*$Y$76)+(AB17*$AA$76) -> 0 | AG17: =+(AD17*$AD$76)+(AE17*$AE$76) -> 0
B18: 8 | C18: Innovaciones Energeticas Inner SA de CV | D18: Loreto | E18: Loreto | F18: Baja California Sur | G18: Fotovoltaica | H18: 50 | I18: - | J18: - | K18: 0 | L18: 0 | M18: 0 | N18: 0 | O18: 0 | P18: 0 | Q18: 0 | R18: 0 | S18: 0 | T18: 0 | U18: 0 | V18: 0 | W18: 0 | X18: 0 | Y18: 0 | Z18: 0 | AA18: 0 | AB18: 0 | AD18: =+(K18*$K$76)+(M18*$M$76)+(N18*$N$76)+(P18*$P$76)+(R18*$R$76)+(T18*$T$76)+(U18*$U$76)+(W18*$W$76)+(Y18*$Y$76)+(AA18*$AA$76) -> 0 | AE18: =+(L18*$K$76)+(M18*$M$76)+(O18*$N$76)+(Q18*$P$76)+(S18*$R$76)+(T18*$T$76)+(V18*$U$76)+(X18*$W$76)+(Z18*$Y$76)+(AB18*$AA$76) -> 0 | AG18: =+(AD18*$AD$76)+(AE18*$AE$76) -> 0
B19: 9 | C19: Invenergy Solar Development Mexico S de RL de CV | D19: Loreto Energy Center | E19: Loreto | F19: Baja California Sur | G19: Fotovoltaica | H19: 30 | I19: - | J19: - | K19: 0 | L19: 0 | M19: 0 | N19: 0 | O19: 0 | P19: 0 | Q19: 0 | R19: 0 | S19: 0 | T19: 0 | U19: 0 | V19: 0 | W19: 0 | X19: 0 | Y19: 0 | Z19: 0 | AA19: 0 | AB19: 0 | AD19: =+(K19*$K$76)+(M19*$M$76)+(N19*$N$76)+(P19*$P$76)+(R19*$R$76)+(T19*$T$76)+(U19*$U$76)+(W19*$W$76)+(Y19*$Y$76)+(AA19*$AA$76) -> 0 | AE19: =+(L19*$K$76)+(M19*$M$76)+(O19*$N$76)+(Q19*$P$76)+(S19*$R$76)+(T19*$T$76)+(V19*$U$76)+(X19*$W$76)+(Z19*$Y$76)+(AB19*$AA$76) -> 0 | AG19: =+(AD19*$AD$76)+(AE19*$AE$76) -> 0
B20: 10 | C20: Soluciones Energeticas Para La Transformacion BCS S A P I de CV | D20: Proyecto Solar San Jose Del Cabo | E20: Los Cabos | F20: Baja California Sur | G20: Fotovoltaica | H20: 30 | I20: - | J20: - | K20: 0 | L20: 0 | M20: 0 | N20: 0 | O20: 0 | P20: 0 | Q20: 0 | R20: 0 | S20: 0 | T20: 0 | U20: 0 | V20: 0 | W20: 0 | X20: 0 | Y20: 0 | Z20: 0 | AA20: 0 | AB20: 0 | AD20: =+(K20*$K$76)+(M20*$M$76)+(N20*$N$76)+(P20*$P$76)+(R20*$R$76)+(T20*$T$76)+(U20*$U$76)+(W20*$W$76)+(Y20*$Y$76)+(AA20*$AA$76) -> 0 | AE20: =+(L20*$K$76)+(M20*$M$76)+(O20*$N$76)+(Q20*$P$76)+(S20*$R$76)+(T20*$T$76)+(V20*$U$76)+(X20*$W$76)+(Z20*$Y$76)+(AB20*$AA$76) -> 0 | AG20: =+(AD20*$AD$76)+(AE20*$AE$76) -> 0
B21: 11 | C21: BU ST Services S de RL de CV | D21: Santiago Solar | E21: Los Cabos | F21: Baja California Sur | G21: Fotovoltaica | H21: 40 | I21: - | J21: - | K21: 0 | L21: 0 | M21: 0 | N21: 0 | O21: 0 | P21: 0 | Q21: 0 | R21: 0 | S21: 0 | T21: 0 | U21: 0 | V21: 0 | W21: 0 | X21: 0 | Y21: 0 | Z21: 0 | AA21: 0 | AB21: 0 | AD21: =+(K21*$K$76)+(M21*$M$76)+(N21*$N$76)+(P21*$P$76)+(R21*$R$76)+(T21*$T$76)+(U21*$U$76)+(W21*$W$76)+(Y21*$Y$76)+(AA21*$AA$76) -> 0 | AE21: =+(L21*$K$76)+(M21*$M$76)+(O21*$N$76)+(Q21*$P$76)+(S21*$R$76)+(T21*$T$76)+(V21*$U$76)+(X21*$W$76)+(Z21*$Y$76)+(AB21*$AA$76) -> 0 | AG21: =+(AD21*$AD$76)+(AE21*$AE$76) -> 0
B22: 12 | C22: Atlacomulco Solar Fotovoltaica SA de CV | D22: Atlacomulco | E22: Jocotitlán | F22: Estado de México | G22: Fotovoltaica | H22: 100 | I22: - | J22: - | K22: 0 | L22: 0 | M22: 0 | N22: 0 | O22: 0 | P22: 0 | Q22: 0 | R22: 0 | S22: 0 | T22: 0 | U22: 0 | V22: 0 | W22: 0 | X22: 0 | Y22: 0 | Z22: 0 | AA22: 0 | AB22: 0 | AD22: =+(K22*$K$76)+(M22*$M$76)+(N22*$N$76)+(P22*$P$76)+(R22*$R$76)+(T22*$T$76)+(U22*$U$76)+(W22*$W$76)+(Y22*$Y$76)+(AA22*$AA$76) -> 0 | AE22: =+(L22*$K$76)+(M22*$M$76)+(O22*$N$76)+(Q22*$P$76)+(S22*$R$76)+(T22*$T$76)+(V22*$U$76)+(X22*$W$76)+(Z22*$Y$76)+(AB22*$AA$76) -> 0 | AG22: =+(AD22*$AD$76)+(AE22*$AE$76) -> 0
... B74: 64 | C74: PV El Tintillo Solar SG S de RL de CV | D74: PV Tecamachalco Solar | E74: Tecamachalco | F74: Puebla | G74: Fotovoltaica | H74: 36 | I74: - | J74: - | K74: 0 | L74: 0 | M74: 0 | N74: 0 | O74: 0 | P74: 0 | Q74: 0 | R74: 0 | S74: 0 | T74: 0 | U74: 0 | V74: 0 | W74: 0 | X74: 0 | Y74: 0 | Z74: 0 | AA74: 0 | AB74: 0 | AD74: =+(K74*$K$76)+(M74*$M$76)+(N74*$N$76)+(P74*$P$76)+(R74*$R$76)+(T74*$T$76)+(U74*$U$76)+(W74*$W$76)+(Y74*$Y$76)+(AA74*$AA$76) -> 0 | AE74: =+(L74*$K$76)+(M74*$M$76)+(O74*$N$76)+(Q74*$P$76)+(S74*$R$76)+(T74*$T$76)+(V74*$U$76)+(X74*$W$76)+(Z74*$Y$76)+(AB74*$AA$76) -> 0 | AG74: =+(AD74*$AD$76)+(AE74*$AE$76) -> 0
K75: Ponderan | M75: Pondera | N75: Ponderan | R75: Ponderan | T75: Pondera | U75: Ponderan | W75: Ponderan | Y75: Ponderan | AA75: Ponderan | AD75: Pondera | AE75: Pondera
K76: 0.1 | M76: 0.1 | N76: 0.2 | P76: 0.1 | R76: 0.2 | T76: 0.1 | U76: 0.05 | W76: 0.05 | Y76: 0.05 | AA76: 0.05 | AD76: 0.8 | AE76: 0.2
D78: (*) | E78: Indica Proyecto que se va a segunda ronda de Proyectos Mixtos
D79: (**) | E79: Indica Proyecto que no puede ser ingresado al SEN sin que entren obras de refuerzo que no son responsabilidad del Proyecto, es decir, por un tercero; según CENACE
AD119: 0
AD120: 1

Sheet BASE_DE_DATOS
A1: Datos Relevantes del Proyecto | S1: Estatus de avance de los trámites de acuerdo con las reglas | AK1: Valores de avance de los trámites de acuerdo con las reglas
S2: Derechos Inmobiliarios | U2: Estudios de Interconexión | V2: MIA / DTU | X2: ETJ | Z2: EVIS / MISSE y Consulta indígena | AC2: INAH | AE2: PEMEX | AG2: CONAGUA | AI2: AFAC | AK2: Derechos Inmobiliarios | AM2: Estudios de Interconexión | AN2: MIA / DTU | AP2: ETJ | AR2: EVIS / MISSE y Consulta indígena | AU2: INAH | AW2: PEMEX | AY2: CONAGUA | BA2: AFAC
A3: No. | B3: ID_VUPE | C3: Región | D3: Grupo de Interés Económico | E3: Proyecto | F3: Entidad | G3: Municipio | H3: Tecnología | I3: Capacidad Neta [MW] | J3: Porcentaje BESS [%] | K3: Almacenamiento BESS [MW] | L3: HORAS DE ALMACENAMIENTO | M3: Energía por horas [MWh] | N3: Inicio de Inversión | O3: Fin de Construcción | P3: Fecha firma de contrato | Q3: CAPEX | R3: PRIORI | S3: DI_P_ESTATUS | T3: DI_LT_ESTATUS | U3: ES_INT_ESTATUS | V3: A_MIA_P_ESTATUS | W3: A_MIA_LT_ESTATUS | X3: A_ETJ_P_ESTATUS | Y3: A_ETJ_LT_ESTATUS | Z3: S_MISSE_C_ESTATUS | AA3: S_MISSE_LT_ESTATUS | AB3: S_CONS_ESTATUS | AC3: INAH_C_ESTATUS | AD3: INAH_LT_ESTATUS | AE3: PEMEX_C_ESTATUS | AF3: PEMEX_LT_ESTATUS | AG3: CONA_C_ESTATUS | AH3: CONA_LT_ESTATUS | AI3: AFAC_C_ESTATUS | AJ3: AFAC_LT_ESTATUS | AK3: DI_P | AL3: DI_LT | AM3: ES_INT | AN3: A_MIA_P | AO3: A_MIA_LT | AP3: A_ETJ_P | AQ3: A_ETJ_LT | AR3: S_MISSE_C | AS3: S_MISSE_LT | AT3: S_CONS | AU3: INAH_C | AV3: INAH_LT | AW3: PEMEX_C | AX3: PEMEX_LT | AY3: CONA_C | AZ3: CONA_LT | BA3: AFAC_C | BB3: AFAC_LT
A4: 1 | B4: 573 | C4: Baja California | D4: Invenergy Solar Development Mexico S de RL de CV | E4: Bura Energy Center II | F4: Baja California | G4: Tecate | H4: Fotovoltaica | I4: 38 | J4: SIN DATO | K4: SIN DATO | L4: SIN DATO | M4: SIN DATO | N4: SIN DATO | O4: SIN DATO | P4: SIN DATO | Q4: SIN DATO | R4: NoP | S4: Pendiente | T4: Pendiente | U4: Pendiente | V4: Pendiente | W4: Pendiente | X4: Pendiente | Y4: Pendiente | Z4: Pendiente | AA4: Pendiente | AB4: Pendiente | AC4: Pendiente | AD4: Pendiente | AE4: Pendiente | AF4: Pendiente | AG4: Pendiente | AH4: Pendiente | AI4: Pendiente | AJ4: Pendiente | AK4: =IF(S4="Pendiente",0%,IF(S4="En elaboración",20%,IF(S4="En evaluación",50%,IF(S4="Requerimiento",75%,IF(S4="En actualización",75%,IF(S4="En dictaminación",85%,IF(S4="Liberado",100%,IF(S4="N/A",100%,"ERROR")))))))) -> 0 | AL4: =IF(T4="Pendiente",0%,IF(T4="En elaboración",20%,IF(T4="En evaluación",50%,IF(T4="Requerimiento",75%,IF(T4="En actualización",75%,IF(T4="En dictaminación",85%,IF(T4="Liberado",100%,IF(T4="N/A",100%,"ERROR")))))))) -> 0 | AM4: =IF(U4="Pendiente",0%,IF(U4="En elaboración",20%,IF(U4="En evaluación",50%,IF(U4="Requerimiento",75%,IF(U4="En actualización",75%,IF(U4="En dictaminación",85%,IF(U4="Liberado",100%,IF(U4="N/A",100%,"ERROR")))))))) -> 0 | AN4: =IF(V4="Pendiente",0%,IF(V4="En elaboración",20%,IF(V4="En evaluación",50%,IF(V4="Requerimiento",75%,IF(V4="En actualización",75%,IF(V4="En dictaminación",85%,IF(V4="Liberado",100%,IF(V4="N/A",100%,"ERROR")))))))) -> 0 | AO4: =IF(W4="Pendiente",0%,IF(W4="En elaboración",20%,IF(W4="En evaluación",50%,IF(W4="Requerimiento",75%,IF(W4="En actualización",75%,IF(W4="En dictaminación",85%,IF(W4="Liberado",100%,IF(W4="N/A",100%,"ERROR")))))))) -> 0 | AP4: =IF(X4="Pendiente",0%,IF(X4="En elaboración",20%,IF(X4="En evaluación",50%,IF(X4="Requerimiento",75%,IF(X4="En actualización",75%,IF(X4="En dictaminación",85%,IF(X4="Liberado",100%,IF(X4="N/A",100%,"ERROR")))))))) -> 0 | AQ4: =IF(Y4="Pendiente",0%,IF(Y4="En elaboración",20%,IF(Y4="En evaluación",50%,IF(Y4="Requerimiento",75%,IF(Y4="En actualización",75%,IF(Y4="En dictaminación",85%,IF(Y4="Liberado",100%,IF(Y4="N/A",100%,"ERROR")))))))) -> 0 | AR4: =IF(Z4="Pendiente",0%,IF(Z4="En elaboración",20%,IF(Z4="En evaluación",50%,IF(Z4="Requerimiento",75%,IF(Z4="En actualización",75%,IF(Z4="En dictaminación",85%,IF(Z4="Liberado",100%,IF(Z4="N/A",100%,"ERROR")))))))) -> 0 | ... BB4: =IF(AJ4="Pendiente",0%,IF(AJ4="En elaboración",20%,IF(AJ4="En evaluación",50%,IF(AJ4="Requerimiento",75%,IF(AJ4="En actualización",75%,IF(AJ4="En dictaminación",85%,IF(AJ4="Liberado",100%,IF(AJ4="N/A",100%,"ERROR")))))))) -> 0
A5: 2 | B5: 70 | C5: Baja California | D5: Energica Tenedora de Mexico SA de CV | E5: CFE Cerro Prieto | F5: Baja California | G5: Mexicali | H5: Fotovoltaica | I5: 215 | J5: SIN DATO | K5: SIN DATO | L5: SIN DATO | M5: SIN DATO | N5: SIN DATO | O5: SIN DATO | P5: SIN DATO | Q5: SIN DATO | R5: NoP | S5: Pendiente | T5: Pendiente | U5: Pendiente | V5: Pendiente | W5: Pendiente | X5: Pendiente | Y5: Pendiente | Z5: Pendiente | AA5: Pendiente | AB5: Pendiente | AC5: Pendiente | AD5: Pendiente | AE5: Pendiente | AF5: Pendiente | AG5: Pendiente | AH5: Pendiente | AI5: Pendiente | AJ5: Pendiente | AK5: =IF(S5="Pendiente",0%,IF(S5="En elaboración",20%,IF(S5="En evaluación",50%,IF(S5="Requerimiento",75%,IF(S5="En actualización",75%,IF(S5="En dictaminación",85%,IF(S5="Liberado",100%,IF(S5="N/A",100%,"ERROR")))))))) -> 0 | AL5: =IF(T5="Pendiente",0%,IF(T5="En elaboración",20%,IF(T5="En evaluación",50%,IF(T5="Requerimiento",75%,IF(T5="En actualización",75%,IF(T5="En dictaminación",85%,IF(T5="Liberado",100%,IF(T5="N/A",100%,"ERROR")))))))) -> 0 | AM5: =IF(U5="Pendiente",0%,IF(U5="En elaboración",20%,IF(U5="En evaluación",50%,IF(U5="Requerimiento",75%,IF(U5="En actualización",75%,IF(U5="En dictaminación",85%,IF(U5="Liberado",100%,IF(U5="N/A",100%,"ERROR")))))))) -> 0 | AN5: =IF(V5="Pendiente",0%,IF(V5="En elaboración",20%,IF(V5="En evaluación",50%,IF(V5="Requerimiento",75%,IF(V5="En actualización",75%,IF(V5="En dictaminación",85%,IF(V5="Liberado",100%,IF(V5="N/A",100%,"ERROR")))))))) -> 0 | AO5: =IF(W5="Pendiente",0%,IF(W5="En elaboración",20%,IF(W5="En evaluación",50%,IF(W5="Requerimiento",75%,IF(W5="En actualización",75%,IF(W5="En dictaminación",85%,IF(W5="Liberado",100%,IF(W5="N/A",100%,"ERROR")))))))) -> 0 | AP5: =IF(X5="Pendiente",0%,IF(X5="En elaboración",20%,IF(X5="En evaluación",50%,IF(X5="Requerimiento",75%,IF(X5="En actualización",75%,IF(X5="En dictaminación",85%,IF(X5="Liberado",100%,IF(X5="N/A",100%,"ERROR")))))))) -> 0 | AQ5: =IF(Y5="Pendiente",0%,IF(Y5="En elaboración",20%,IF(Y5="En evaluación",50%,IF(Y5="Requerimiento",75%,IF(Y5="En actualización",75%,IF(Y5="En dictaminación",85%,IF(Y5="Liberado",100%,IF(Y5="N/A",100%,"ERROR")))))))) -> 0 | AR5: =IF(Z5="Pendiente",0%,IF(Z5="En elaboración",20%,IF(Z5="En evaluación",50%,IF(Z5="Requerimiento",75%,IF(Z5="En actualización",75%,IF(Z5="En dictaminación",85%,IF(Z5="Liberado",100%,IF(Z5="N/A",100%,"ERROR")))))))) -> 0 | ... BB5: =IF(AJ5="Pendiente",0%,IF(AJ5="En elaboración",20%,IF(AJ5="En evaluación",50%,IF(AJ5="Requerimiento",75%,IF(AJ5="En actualización",75%,IF(AJ5="En dictaminación",85%,IF(AJ5="Liberado",100%,IF(AJ5="N/A",100%,"ERROR")))))))) -> 0
A6: 3 | B6: 58 | C6: Baja California | D6: Energica Tenedora de Mexico SA de CV | E6: ICA Punta Colonet | F6: Baja California | G6: Ensenada | H6: Fotovoltaica | I6: 120 | J6: SIN DATO | K6: SIN DATO | L6: SIN DATO | M6: SIN DATO | N6: SIN DATO | O6: SIN DATO | P6: SIN DATO | Q6: SIN DATO | R6: NoP | S6: Pendiente | T6: Pendiente | U6: Pendiente | V6: Pendiente | W6: Pendiente | X6: Pendiente | Y6: Pendiente | Z6: Pendiente | AA6: Pendiente | AB6: Pendiente | AC6: Pendiente | AD6: Pendiente | AE6: Pendiente | AF6: Pendiente | AG6: Pendiente | AH6: Pendiente | AI6: Pendiente | AJ6: Pendiente | AK6: =IF(S6="Pendiente",0%,IF(S6="En elaboración",20%,IF(S6="En evaluación",50%,IF(S6="Requerimiento",75%,IF(S6="En actualización",75%,IF(S6="En dictaminación",85%,IF(S6="Liberado",100%,IF(S6="N/A",100%,"ERROR")))))))) -> 0 | AL6: =IF(T6="Pendiente",0%,IF(T6="En elaboración",20%,IF(T6="En evaluación",50%,IF(T6="Requerimiento",75%,IF(T6="En actualización",75%,IF(T6="En dictaminación",85%,IF(T6="Liberado",100%,IF(T6="N/A",100%,"ERROR")))))))) -> 0 | AM6: =IF(U6="Pendiente",0%,IF(U6="En elaboración",20%,IF(U6="En evaluación",50%,IF(U6="Requerimiento",75%,IF(U6="En actualización",75%,IF(U6="En dictaminación",85%,IF(U6="Liberado",100%,IF(U6="N/A",100%,"ERROR")))))))) -> 0 | AN6: =IF(V6="Pendiente",0%,IF(V6="En elaboración",20%,IF(V6="En evaluación",50%,IF(V6="Requerimiento",75%,IF(V6="En actualización",75%,IF(V6="En dictaminación",85%,IF(V6="Liberado",100%,IF(V6="N/A",100%,"ERROR")))))))) -> 0 | AO6: =IF(W6="Pendiente",0%,IF(W6="En elaboración",20%,IF(W6="En evaluación",50%,IF(W6="Requerimiento",75%,IF(W6="En actualización",75%,IF(W6="En dictaminación",85%,IF(W6="Liberado",100%,IF(W6="N/A",100%,"ERROR")))))))) -> 0 | AP6: =IF(X6="Pendiente",0%,IF(X6="En elaboración",20%,IF(X6="En evaluación",50%,IF(X6="Requerimiento",75%,IF(X6="En actualización",75%,IF(X6="En dictaminación",85%,IF(X6="Liberado",100%,IF(X6="N/A",100%,"ERROR")))))))) -> 0 | AQ6: =IF(Y6="Pendiente",0%,IF(Y6="En elaboración",20%,IF(Y6="En evaluación",50%,IF(Y6="Requerimiento",75%,IF(Y6="En actualización",75%,IF(Y6="En dictaminación",85%,IF(Y6="Liberado",100%,IF(Y6="N/A",100%,"ERROR")))))))) -> 0 | AR6: =IF(Z6="Pendiente",0%,IF(Z6="En elaboración",20%,IF(Z6="En evaluación",50%,IF(Z6="Requerimiento",75%,IF(Z6="En actualización",75%,IF(Z6="En dictaminación",85%,IF(Z6="Liberado",100%,IF(Z6="N/A",100%,"ERROR")))))))) -> 0 | ... BB6: =IF(AJ6="Pendiente",0%,IF(AJ6="En elaboración",20%,IF(AJ6="En evaluación",50%,IF(AJ6="Requerimiento",75%,IF(AJ6="En actualización",75%,IF(AJ6="En dictaminación",85%,IF(AJ6="Liberado",100%,IF(AJ6="N/A",100%,"ERROR")))))))) -> 0
A7: 4 | B7: 68 | C7: Baja California | D7: Energica Tenedora de Mexico SA de CV | E7: ICA San Luis Rio Colorado | F7: Sonora | G7: San Luis Río Colorado | H7: Fotovoltaica | I7: 100 | J7: SIN DATO | K7: SIN DATO | L7: SIN DATO | M7: SIN DATO | N7: SIN DATO | O7: SIN DATO | P7: SIN DATO | Q7: SIN DATO | R7: NoP | S7: Pendiente | T7: Pendiente | U7: Pendiente | V7: Pendiente | W7: Pendiente | X7: Pendiente | Y7: Pendiente | Z7: Pendiente | AA7: Pendiente | AB7: Pendiente | AC7: Pendiente | AD7: Pendiente | AE7: Pendiente | AF7: Pendiente | AG7: Pendiente | AH7: Pendiente | AI7: Pendiente | AJ7: Pendiente | AK7: =IF(S7="Pendiente",0%,IF(S7="En elaboración",20%,IF(S7="En evaluación",50%,IF(S7="Requerimiento",75%,IF(S7="En actualización",75%,IF(S7="En dictaminación",85%,IF(S7="Liberado",100%,IF(S7="N/A",100%,"ERROR")))))))) -> 0 | AL7: =IF(T7="Pendiente",0%,IF(T7="En elaboración",20%,IF(T7="En evaluación",50%,IF(T7="Requerimiento",75%,IF(T7="En actualización",75%,IF(T7="En dictaminación",85%,IF(T7="Liberado",100%,IF(T7="N/A",100%,"ERROR")))))))) -> 0 | AM7: =IF(U7="Pendiente",0%,IF(U7="En elaboración",20%,IF(U7="En evaluación",50%,IF(U7="Requerimiento",75%,IF(U7="En actualización",75%,IF(U7="En dictaminación",85%,IF(U7="Liberado",100%,IF(U7="N/A",100%,"ERROR")))))))) -> 0 | AN7: =IF(V7="Pendiente",0%,IF(V7="En elaboración",20%,IF(V7="En evaluación",50%,IF(V7="Requerimiento",75%,IF(V7="En actualización",75%,IF(V7="En dictaminación",85%,IF(V7="Liberado",100%,IF(V7="N/A",100%,"ERROR")))))))) -> 0 | AO7: =IF(W7="Pendiente",0%,IF(W7="En elaboración",20%,IF(W7="En evaluación",50%,IF(W7="Requerimiento",75%,IF(W7="En actualización",75%,IF(W7="En dictaminación",85%,IF(W7="Liberado",100%,IF(W7="N/A",100%,"ERROR")))))))) -> 0 | AP7: =IF(X7="Pendiente",0%,IF(X7="En elaboración",20%,IF(X7="En evaluación",50%,IF(X7="Requerimiento",75%,IF(X7="En actualización",75%,IF(X7="En dictaminación",85%,IF(X7="Liberado",100%,IF(X7="N/A",100%,"ERROR")))))))) -> 0 | AQ7: =IF(Y7="Pendiente",0%,IF(Y7="En elaboración",20%,IF(Y7="En evaluación",50%,IF(Y7="Requerimiento",75%,IF(Y7="En actualización",75%,IF(Y7="En dictaminación",85%,IF(Y7="Liberado",100%,IF(Y7="N/A",100%,"ERROR")))))))) -> 0 | AR7: =IF(Z7="Pendiente",0%,IF(Z7="En elaboración",20%,IF(Z7="En evaluación",50%,IF(Z7="Requerimiento",75%,IF(Z7="En actualización",75%,IF(Z7="En dictaminación",85%,IF(Z7="Liberado",100%,IF(Z7="N/A",100%,"ERROR")))))))) -> 0 | ... BB7: =IF(AJ7="Pendiente",0%,IF(AJ7="En elaboración",20%,IF(AJ7="En evaluación",50%,IF(AJ7="Requerimiento",75%,IF(AJ7="En actualización",75%,IF(AJ7="En dictaminación",85%,IF(AJ7="Liberado",100%,IF(AJ7="N/A",100%,"ERROR")))))))) -> 0
A8: 5 | B8: 216 | C8: Baja California | D8: PYE Electrificaciones S de RL de CV | E8: Planta Solar Fotovoltaica Mesa Andrade I | F8: Baja California | G8: Mexicali | H8: Fotovoltaica | I8: 132 | J8: SIN DATO | K8: SIN DATO | L8: SIN DATO | M8: SIN DATO | N8: SIN DATO | O8: SIN DATO | P8: SIN DATO | Q8: SIN DATO | R8: NoP | S8: Pendiente | T8: Pendiente | U8: Pendiente | V8: Pendiente | W8: Pendiente | X8: Pendiente | Y8: Pendiente | Z8: Pendiente | AA8: Pendiente | AB8: Pendiente | AC8: Pendiente | AD8: Pendiente | AE8: Pendiente | AF8: Pendiente | AG8: Pendiente | AH8: Pendiente | AI8: Pendiente | AJ8: Pendiente | AK8: =IF(S8="Pendiente",0%,IF(S8="En elaboración",20%,IF(S8="En evaluación",50%,IF(S8="Requerimiento",75%,IF(S8="En actualización",75%,IF(S8="En dictaminación",85%,IF(S8="Liberado",100%,IF(S8="N/A",100%,"ERROR")))))))) -> 0 | AL8: =IF(T8="Pendiente",0%,IF(T8="En elaboración",20%,IF(T8="En evaluación",50%,IF(T8="Requerimiento",75%,IF(T8="En actualización",75%,IF(T8="En dictaminación",85%,IF(T8="Liberado",100%,IF(T8="N/A",100%,"ERROR")))))))) -> 0 | AM8: =IF(U8="Pendiente",0%,IF(U8="En elaboración",20%,IF(U8="En evaluación",50%,IF(U8="Requerimiento",75%,IF(U8="En actualización",75%,IF(U8="En dictaminación",85%,IF(U8="Liberado",100%,IF(U8="N/A",100%,"ERROR")))))))) -> 0 | AN8: =IF(V8="Pendiente",0%,IF(V8="En elaboración",20%,IF(V8="En evaluación",50%,IF(V8="Requerimiento",75%,IF(V8="En actualización",75%,IF(V8="En dictaminación",85%,IF(V8="Liberado",100%,IF(V8="N/A",100%,"ERROR")))))))) -> 0 | AO8: =IF(W8="Pendiente",0%,IF(W8="En elaboración",20%,IF(W8="En evaluación",50%,IF(W8="Requerimiento",75%,IF(W8="En actualización",75%,IF(W8="En dictaminación",85%,IF(W8="Liberado",100%,IF(W8="N/A",100%,"ERROR")))))))) -> 0 | AP8: =IF(X8="Pendiente",0%,IF(X8="En elaboración",20%,IF(X8="En evaluación",50%,IF(X8="Requerimiento",75%,IF(X8="En actualización",75%,IF(X8="En dictaminación",85%,IF(X8="Liberado",100%,IF(X8="N/A",100%,"ERROR")))))))) -> 0 | AQ8: =IF(Y8="Pendiente",0%,IF(Y8="En elaboración",20%,IF(Y8="En evaluación",50%,IF(Y8="Requerimiento",75%,IF(Y8="En actualización",75%,IF(Y8="En dictaminación",85%,IF(Y8="Liberado",100%,IF(Y8="N/A",100%,"ERROR")))))))) -> 0 | AR8: =IF(Z8="Pendiente",0%,IF(Z8="En elaboración",20%,IF(Z8="En evaluación",50%,IF(Z8="Requerimiento",75%,IF(Z8="En actualización",75%,IF(Z8="En dictaminación",85%,IF(Z8="Liberado",100%,IF(Z8="N/A",100%,"ERROR")))))))) -> 0 | ... BB8: =IF(AJ8="Pendiente",0%,IF(AJ8="En elaboración",20%,IF(AJ8="En evaluación",50%,IF(AJ8="Requerimiento",75%,IF(AJ8="En actualización",75%,IF(AJ8="En dictaminación",85%,IF(AJ8="Liberado",100%,IF(AJ8="N/A",100%,"ERROR")))))))) -> 0
A9: 6 | B9: 598 | C9: Baja California | D9: Energia Firme Sigma S A P I de CV | E9: San Felipe Solar | F9: Baja California | G9: San Felipe | H9: Fotovoltaica | I9: 100 | J9: SIN DATO | K9: SIN DATO | L9: SIN DATO | M9: SIN DATO | N9: SIN DATO | O9: SIN DATO | P9: SIN DATO | Q9: SIN DATO | R9: NoP | S9: Pendiente | T9: Pendiente | U9: Pendiente | V9: Pendiente | W9: Pendiente | X9: Pendiente | Y9: Pendiente | Z9: Pendiente | AA9: Pendiente | AB9: Pendiente | AC9: Pendiente | AD9: Pendiente | AE9: Pendiente | AF9: Pendiente | AG9: Pendiente | AH9: Pendiente | AI9: Pendiente | AJ9: Pendiente | AK9: =IF(S9="Pendiente",0%,IF(S9="En elaboración",20%,IF(S9="En evaluación",50%,IF(S9="Requerimiento",75%,IF(S9="En actualización",75%,IF(S9="En dictaminación",85%,IF(S9="Liberado",100%,IF(S9="N/A",100%,"ERROR")))))))) -> 0 | AL9: =IF(T9="Pendiente",0%,IF(T9="En elaboración",20%,IF(T9="En evaluación",50%,IF(T9="Requerimiento",75%,IF(T9="En actualización",75%,IF(T9="En dictaminación",85%,IF(T9="Liberado",100%,IF(T9="N/A",100%,"ERROR")))))))) -> 0 | AM9: =IF(U9="Pendiente",0%,IF(U9="En elaboración",20%,IF(U9="En evaluación",50%,IF(U9="Requerimiento",75%,IF(U9="En actualización",75%,IF(U9="En dictaminación",85%,IF(U9="Liberado",100%,IF(U9="N/A",100%,"ERROR")))))))) -> 0 | AN9: =IF(V9="Pendiente",0%,IF(V9="En elaboración",20%,IF(V9="En evaluación",50%,IF(V9="Requerimiento",75%,IF(V9="En actualización",75%,IF(V9="En dictaminación",85%,IF(V9="Liberado",100%,IF(V9="N/A",100%,"ERROR")))))))) -> 0 | AO9: =IF(W9="Pendiente",0%,IF(W9="En elaboración",20%,IF(W9="En evaluación",50%,IF(W9="Requerimiento",75%,IF(W9="En actualización",75%,IF(W9="En dictaminación",85%,IF(W9="Liberado",100%,IF(W9="N/A",100%,"ERROR")))))))) -> 0 | AP9: =IF(X9="Pendiente",0%,IF(X9="En elaboración",20%,IF(X9="En evaluación",50%,IF(X9="Requerimiento",75%,IF(X9="En actualización",75%,IF(X9="En dictaminación",85%,IF(X9="Liberado",100%,IF(X9="N/A",100%,"ERROR")))))))) -> 0 | AQ9: =IF(Y9="Pendiente",0%,IF(Y9="En elaboración",20%,IF(Y9="En evaluación",50%,IF(Y9="Requerimiento",75%,IF(Y9="En actualización",75%,IF(Y9="En dictaminación",85%,IF(Y9="Liberado",100%,IF(Y9="N/A",100%,"ERROR")))))))) -> 0 | AR9: =IF(Z9="Pendiente",0%,IF(Z9="En elaboración",20%,IF(Z9="En evaluación",50%,IF(Z9="Requerimiento",75%,IF(Z9="En actualización",75%,IF(Z9="En dictaminación",85%,IF(Z9="Liberado",100%,IF(Z9="N/A",100%,"ERROR")))))))) -> 0 | ... BB9: =IF(AJ9="Pendiente",0%,IF(AJ9="En elaboración",20%,IF(AJ9="En evaluación",50%,IF(AJ9="Requerimiento",75%,IF(AJ9="En actualización",75%,IF(AJ9="En dictaminación",85%,IF(AJ9="Liberado",100%,IF(AJ9="N/A",100%,"ERROR")))))))) -> 0
A10: 7 | B10: 467 | C10: Baja California | D10: Electrica Aselco SA de CV | E10: Insurgentes | F10: Baja California Sur | G10: Comondú | H10: Fotovoltaica | I10: 36.58 | J10: SIN DATO | K10: SIN DATO | L10: SIN DATO | M10: SIN DATO | N10: SIN DATO | O10: SIN DATO | P10: SIN DATO | Q10: SIN DATO | R10: NoP | S10: Pendiente | T10: Pendiente | U10: Pendiente | V10: Pendiente | W10: Pendiente | X10: Pendiente | Y10: Pendiente | Z10: Pendiente | AA10: Pendiente | AB10: Pendiente | AC10: Pendiente | AD10: Pendiente | AE10: Pendiente | AF10: Pendiente | AG10: Pendiente | AH10: Pendiente | AI10: Pendiente | AJ10: Pendiente | AK10: =IF(S10="Pendiente",0%,IF(S10="En elaboración",20%,IF(S10="En evaluación",50%,IF(S10="Requerimiento",75%,IF(S10="En actualización",75%,IF(S10="En dictaminación",85%,IF(S10="Liberado",100%,IF(S10="N/A",100%,"ERROR")))))))) -> 0 | AL10: =IF(T10="Pendiente",0%,IF(T10="En elaboración",20%,IF(T10="En evaluación",50%,IF(T10="Requerimiento",75%,IF(T10="En actualización",75%,IF(T10="En dictaminación",85%,IF(T10="Liberado",100%,IF(T10="N/A",100%,"ERROR")))))))) -> 0 | AM10: =IF(U10="Pendiente",0%,IF(U10="En elaboración",20%,IF(U10="En evaluación",50%,IF(U10="Requerimiento",75%,IF(U10="En actualización",75%,IF(U10="En dictaminación",85%,IF(U10="Liberado",100%,IF(U10="N/A",100%,"ERROR")))))))) -> 0 | AN10: =IF(V10="Pendiente",0%,IF(V10="En elaboración",20%,IF(V10="En evaluación",50%,IF(V10="Requerimiento",75%,IF(V10="En actualización",75%,IF(V10="En dictaminación",85%,IF(V10="Liberado",100%,IF(V10="N/A",100%,"ERROR")))))))) -> 0 | AO10: =IF(W10="Pendiente",0%,IF(W10="En elaboración",20%,IF(W10="En evaluación",50%,IF(W10="Requerimiento",75%,IF(W10="En actualización",75%,IF(W10="En dictaminación",85%,IF(W10="Liberado",100%,IF(W10="N/A",100%,"ERROR")))))))) -> 0 | AP10: =IF(X10="Pendiente",0%,IF(X10="En elaboración",20%,IF(X10="En evaluación",50%,IF(X10="Requerimiento",75%,IF(X10="En actualización",75%,IF(X10="En dictaminación",85%,IF(X10="Liberado",100%,IF(X10="N/A",100%,"ERROR")))))))) -> 0 | AQ10: =IF(Y10="Pendiente",0%,IF(Y10="En elaboración",20%,IF(Y10="En evaluación",50%,IF(Y10="Requerimiento",75%,IF(Y10="En actualización",75%,IF(Y10="En dictaminación",85%,IF(Y10="Liberado",100%,IF(Y10="N/A",100%,"ERROR")))))))) -> 0 | AR10: =IF(Z10="Pendiente",0%,IF(Z10="En elaboración",20%,IF(Z10="En evaluación",50%,IF(Z10="Requerimiento",75%,IF(Z10="En actualización",75%,IF(Z10="En dictaminación",85%,IF(Z10="Liberado",100%,IF(Z10="N/A",100%,"ERROR")))))))) -> 0 | ... BB10: =IF(AJ10="Pendiente",0%,IF(AJ10="En elaboración",20%,IF(AJ10="En evaluación",50%,IF(AJ10="Requerimiento",75%,IF(AJ10="En actualización",75%,IF(AJ10="En dictaminación",85%,IF(AJ10="Liberado",100%,IF(AJ10="N/A",100%,"ERROR")))))))) -> 0
A11: 8 | B11: 508 | C11: Baja California | D11: Innovaciones Energeticas Inner SA de CV | E11: Loreto | F11: Baja California Sur | G11: Loreto | H11: Fotovoltaica | I11: 50 | J11: SIN DATO | K11: SIN DATO | L11: SIN DATO | M11: SIN DATO | N11: SIN DATO | O11: SIN DATO | P11: SIN DATO | Q11: SIN DATO | R11: NoP | S11: Pendiente | T11: Pendiente | U11: Pendiente | V11: Pendiente | W11: Pendiente | X11: Pendiente | Y11: Pendiente | Z11: Pendiente | AA11: Pendiente | AB11: Pendiente | AC11: Pendiente | AD11: Pendiente | AE11: Pendiente | AF11: Pendiente | AG11: Pendiente | AH11: Pendiente | AI11: Pendiente | AJ11: Pendiente | AK11: =IF(S11="Pendiente",0%,IF(S11="En elaboración",20%,IF(S11="En evaluación",50%,IF(S11="Requerimiento",75%,IF(S11="En actualización",75%,IF(S11="En dictaminación",85%,IF(S11="Liberado",100%,IF(S11="N/A",100%,"ERROR")))))))) -> 0 | AL11: =IF(T11="Pendiente",0%,IF(T11="En elaboración",20%,IF(T11="En evaluación",50%,IF(T11="Requerimiento",75%,IF(T11="En actualización",75%,IF(T11="En dictaminación",85%,IF(T11="Liberado",100%,IF(T11="N/A",100%,"ERROR")))))))) -> 0 | AM11: =IF(U11="Pendiente",0%,IF(U11="En elaboración",20%,IF(U11="En evaluación",50%,IF(U11="Requerimiento",75%,IF(U11="En actualización",75%,IF(U11="En dictaminación",85%,IF(U11="Liberado",100%,IF(U11="N/A",100%,"ERROR")))))))) -> 0 | AN11: =IF(V11="Pendiente",0%,IF(V11="En elaboración",20%,IF(V11="En evaluación",50%,IF(V11="Requerimiento",75%,IF(V11="En actualización",75%,IF(V11="En dictaminación",85%,IF(V11="Liberado",100%,IF(V11="N/A",100%,"ERROR")))))))) -> 0 | AO11: =IF(W11="Pendiente",0%,IF(W11="En elaboración",20%,IF(W11="En evaluación",50%,IF(W11="Requerimiento",75%,IF(W11="En actualización",75%,IF(W11="En dictaminación",85%,IF(W11="Liberado",100%,IF(W11="N/A",100%,"ERROR")))))))) -> 0 | AP11: =IF(X11="Pendiente",0%,IF(X11="En elaboración",20%,IF(X11="En evaluación",50%,IF(X11="Requerimiento",75%,IF(X11="En actualización",75%,IF(X11="En dictaminación",85%,IF(X11="Liberado",100%,IF(X11="N/A",100%,"ERROR")))))))) -> 0 | AQ11: =IF(Y11="Pendiente",0%,IF(Y11="En elaboración",20%,IF(Y11="En evaluación",50%,IF(Y11="Requerimiento",75%,IF(Y11="En actualización",75%,IF(Y11="En dictaminación",85%,IF(Y11="Liberado",100%,IF(Y11="N/A",100%,"ERROR")))))))) -> 0 | AR11: =IF(Z11="Pendiente",0%,IF(Z11="En elaboración",20%,IF(Z11="En evaluación",50%,IF(Z11="Requerimiento",75%,IF(Z11="En actualización",75%,IF(Z11="En dictaminación",85%,IF(Z11="Liberado",100%,IF(Z11="N/A",100%,"ERROR")))))))) -> 0 | ... BB11: =IF(AJ11="Pendiente",0%,IF(AJ11="En elaboración",20%,IF(AJ11="En evaluación",50%,IF(AJ11="Requerimiento",75%,IF(AJ11="En actualización",75%,IF(AJ11="En dictaminación",85%,IF(AJ11="Liberado",100%,IF(AJ11="N/A",100%,"ERROR")))))))) -> 0
A12: 9 | B12: 201 | C12: Baja California | D12: Invenergy Solar Development Mexico S de RL de CV | E12: Loreto Energy Center | F12: Baja California Sur | G12: Loreto | H12: Fotovoltaica | I12: 30 | J12: SIN DATO | K12: SIN DATO | L12: SIN DATO | M12: SIN DATO | N12: SIN DATO | O12: SIN DATO | P12: SIN DATO | Q12: SIN DATO | R12: NoP | S12: Pendiente | T12: Pendiente | U12: Pendiente | V12: Pendiente | W12: Pendiente | X12: Pendiente | Y12: Pendiente | Z12: Pendiente | AA12: Pendiente | AB12: Pendiente | AC12: Pendiente | AD12: Pendiente | AE12: Pendiente | AF12: Pendiente | AG12: Pendiente | AH12: Pendiente | AI12: Pendiente | AJ12: Pendiente | AK12: =IF(S12="Pendiente",0%,IF(S12="En elaboración",20%,IF(S12="En evaluación",50%,IF(S12="Requerimiento",75%,IF(S12="En actualización",75%,IF(S12="En dictaminación",85%,IF(S12="Liberado",100%,IF(S12="N/A",100%,"ERROR")))))))) -> 0 | AL12: =IF(T12="Pendiente",0%,IF(T12="En elaboración",20%,IF(T12="En evaluación",50%,IF(T12="Requerimiento",75%,IF(T12="En actualización",75%,IF(T12="En dictaminación",85%,IF(T12="Liberado",100%,IF(T12="N/A",100%,"ERROR")))))))) -> 0 | AM12: =IF(U12="Pendiente",0%,IF(U12="En elaboración",20%,IF(U12="En evaluación",50%,IF(U12="Requerimiento",75%,IF(U12="En actualización",75%,IF(U12="En dictaminación",85%,IF(U12="Liberado",100%,IF(U12="N/A",100%,"ERROR")))))))) -> 0 | AN12: =IF(V12="Pendiente",0%,IF(V12="En elaboración",20%,IF(V12="En evaluación",50%,IF(V12="Requerimiento",75%,IF(V12="En actualización",75%,IF(V12="En dictaminación",85%,IF(V12="Liberado",100%,IF(V12="N/A",100%,"ERROR")))))))) -> 0 | AO12: =IF(W12="Pendiente",0%,IF(W12="En elaboración",20%,IF(W12="En evaluación",50%,IF(W12="Requerimiento",75%,IF(W12="En actualización",75%,IF(W12="En dictaminación",85%,IF(W12="Liberado",100%,IF(W12="N/A",100%,"ERROR")))))))) -> 0 | AP12: =IF(X12="Pendiente",0%,IF(X12="En elaboración",20%,IF(X12="En evaluación",50%,IF(X12="Requerimiento",75%,IF(X12="En actualización",75%,IF(X12="En dictaminación",85%,IF(X12="Liberado",100%,IF(X12="N/A",100%,"ERROR")))))))) -> 0 | AQ12: =IF(Y12="Pendiente",0%,IF(Y12="En elaboración",20%,IF(Y12="En evaluación",50%,IF(Y12="Requerimiento",75%,IF(Y12="En actualización",75%,IF(Y12="En dictaminación",85%,IF(Y12="Liberado",100%,IF(Y12="N/A",100%,"ERROR")))))))) -> 0 | AR12: =IF(Z12="Pendiente",0%,IF(Z12="En elaboración",20%,IF(Z12="En evaluación",50%,IF(Z12="Requerimiento",75%,IF(Z12="En actualización",75%,IF(Z12="En dictaminación",85%,IF(Z12="Liberado",100%,IF(Z12="N/A",100%,"ERROR")))))))) -> 0 | ... BB12: =IF(AJ12="Pendiente",0%,IF(AJ12="En elaboración",20%,IF(AJ12="En evaluación",50%,IF(AJ12="Requerimiento",75%,IF(AJ12="En actualización",75%,IF(AJ12="En dictaminación",85%,IF(AJ12="Liberado",100%,IF(AJ12="N/A",100%,"ERROR")))))))) -> 0
A13: 10 | B13: 658 | C13: Baja California | D13: Soluciones Energeticas Para La Transformacion BCS S A P I de CV | E13: Proyecto Solar San Jose Del Cabo | F13: Baja California Sur | G13: Los Cabos | H13: Fotovoltaica | I13: 30 | J13: SIN DATO | K13: SIN DATO | L13: SIN DATO | M13: SIN DATO | N13: SIN DATO | O13: SIN DATO | P13: SIN DATO | Q13: SIN DATO | R13: NoP | S13: Pendiente | T13: Pendiente | U13: Pendiente | V13: Pendiente | W13: Pendiente | X13: Pendiente | Y13: Pendiente | Z13: Pendiente | AA13: Pendiente | AB13: Pendiente | AC13: Pendiente | AD13: Pendiente | AE13: Pendiente | AF13: Pendiente | AG13: Pendiente | AH13: Pendiente | AI13: Pendiente | AJ13: Pendiente | AK13: =IF(S13="Pendiente",0%,IF(S13="En elaboración",20%,IF(S13="En evaluación",50%,IF(S13="Requerimiento",75%,IF(S13="En actualización",75%,IF(S13="En dictaminación",85%,IF(S13="Liberado",100%,IF(S13="N/A",100%,"ERROR")))))))) -> 0 | AL13: =IF(T13="Pendiente",0%,IF(T13="En elaboración",20%,IF(T13="En evaluación",50%,IF(T13="Requerimiento",75%,IF(T13="En actualización",75%,IF(T13="En dictaminación",85%,IF(T13="Liberado",100%,IF(T13="N/A",100%,"ERROR")))))))) -> 0 | AM13: =IF(U13="Pendiente",0%,IF(U13="En elaboración",20%,IF(U13="En evaluación",50%,IF(U13="Requerimiento",75%,IF(U13="En actualización",75%,IF(U13="En dictaminación",85%,IF(U13="Liberado",100%,IF(U13="N/A",100%,"ERROR")))))))) -> 0 | AN13: =IF(V13="Pendiente",0%,IF(V13="En elaboración",20%,IF(V13="En evaluación",50%,IF(V13="Requerimiento",75%,IF(V13="En actualización",75%,IF(V13="En dictaminación",85%,IF(V13="Liberado",100%,IF(V13="N/A",100%,"ERROR")))))))) -> 0 | AO13: =IF(W13="Pendiente",0%,IF(W13="En elaboración",20%,IF(W13="En evaluación",50%,IF(W13="Requerimiento",75%,IF(W13="En actualización",75%,IF(W13="En dictaminación",85%,IF(W13="Liberado",100%,IF(W13="N/A",100%,"ERROR")))))))) -> 0 | AP13: =IF(X13="Pendiente",0%,IF(X13="En elaboración",20%,IF(X13="En evaluación",50%,IF(X13="Requerimiento",75%,IF(X13="En actualización",75%,IF(X13="En dictaminación",85%,IF(X13="Liberado",100%,IF(X13="N/A",100%,"ERROR")))))))) -> 0 | AQ13: =IF(Y13="Pendiente",0%,IF(Y13="En elaboración",20%,IF(Y13="En evaluación",50%,IF(Y13="Requerimiento",75%,IF(Y13="En actualización",75%,IF(Y13="En dictaminación",85%,IF(Y13="Liberado",100%,IF(Y13="N/A",100%,"ERROR")))))))) -> 0 | AR13: =IF(Z13="Pendiente",0%,IF(Z13="En elaboración",20%,IF(Z13="En evaluación",50%,IF(Z13="Requerimiento",75%,IF(Z13="En actualización",75%,IF(Z13="En dictaminación",85%,IF(Z13="Liberado",100%,IF(Z13="N/A",100%,"ERROR")))))))) -> 0 | ... BB13: =IF(AJ13="Pendiente",0%,IF(AJ13="En elaboración",20%,IF(AJ13="En evaluación",50%,IF(AJ13="Requerimiento",75%,IF(AJ13="En actualización",75%,IF(AJ13="En dictaminación",85%,IF(AJ13="Liberado",100%,IF(AJ13="N/A",100%,"ERROR")))))))) -> 0
A14: 11 | B14: 684 | C14: Baja California | D14: BU ST Services S de RL de CV | E14: Santiago Solar | F14: Baja California Sur | G14: Los Cabos | H14: Fotovoltaica | I14: 40 | J14: SIN DATO | K14: SIN DATO | L14: SIN DATO | M14: SIN DATO | N14: SIN DATO | O14: SIN DATO | P14: SIN DATO | Q14: SIN DATO | R14: NoP | S14: Pendiente | T14: Pendiente | U14: Pendiente | V14: Pendiente | W14: Pendiente | X14: Pendiente | Y14: Pendiente | Z14: Pendiente | AA14: Pendiente | AB14: Pendiente | AC14: Pendiente | AD14: Pendiente | AE14: Pendiente | AF14: Pendiente | AG14: Pendiente | AH14: Pendiente | AI14: Pendiente | AJ14: Pendiente | AK14: =IF(S14="Pendiente",0%,IF(S14="En elaboración",20%,IF(S14="En evaluación",50%,IF(S14="Requerimiento",75%,IF(S14="En actualización",75%,IF(S14="En dictaminación",85%,IF(S14="Liberado",100%,IF(S14="N/A",100%,"ERROR")))))))) -> 0 | AL14: =IF(T14="Pendiente",0%,IF(T14="En elaboración",20%,IF(T14="En evaluación",50%,IF(T14="Requerimiento",75%,IF(T14="En actualización",75%,IF(T14="En dictaminación",85%,IF(T14="Liberado",100%,IF(T14="N/A",100%,"ERROR")))))))) -> 0 | AM14: =IF(U14="Pendiente",0%,IF(U14="En elaboración",20%,IF(U14="En evaluación",50%,IF(U14="Requerimiento",75%,IF(U14="En actualización",75%,IF(U14="En dictaminación",85%,IF(U14="Liberado",100%,IF(U14="N/A",100%,"ERROR")))))))) -> 0 | AN14: =IF(V14="Pendiente",0%,IF(V14="En elaboración",20%,IF(V14="En evaluación",50%,IF(V14="Requerimiento",75%,IF(V14="En actualización",75%,IF(V14="En dictaminación",85%,IF(V14="Liberado",100%,IF(V14="N/A",100%,"ERROR")))))))) -> 0 | AO14: =IF(W14="Pendiente",0%,IF(W14="En elaboración",20%,IF(W14="En evaluación",50%,IF(W14="Requerimiento",75%,IF(W14="En actualización",75%,IF(W14="En dictaminación",85%,IF(W14="Liberado",100%,IF(W14="N/A",100%,"ERROR")))))))) -> 0 | AP14: =IF(X14="Pendiente",0%,IF(X14="En elaboración",20%,IF(X14="En evaluación",50%,IF(X14="Requerimiento",75%,IF(X14="En actualización",75%,IF(X14="En dictaminación",85%,IF(X14="Liberado",100%,IF(X14="N/A",100%,"ERROR")))))))) -> 0 | AQ14: =IF(Y14="Pendiente",0%,IF(Y14="En elaboración",20%,IF(Y14="En evaluación",50%,IF(Y14="Requerimiento",75%,IF(Y14="En actualización",75%,IF(Y14="En dictaminación",85%,IF(Y14="Liberado",100%,IF(Y14="N/A",100%,"ERROR")))))))) -> 0 | AR14: =IF(Z14="Pendiente",0%,IF(Z14="En elaboración",20%,IF(Z14="En evaluación",50%,IF(Z14="Requerimiento",75%,IF(Z14="En actualización",75%,IF(Z14="En dictaminación",85%,IF(Z14="Liberado",100%,IF(Z14="N/A",100%,"ERROR")))))))) -> 0 | ... BB14: =IF(AJ14="Pendiente",0%,IF(AJ14="En elaboración",20%,IF(AJ14="En evaluación",50%,IF(AJ14="Requerimiento",75%,IF(AJ14="En actualización",75%,IF(AJ14="En dictaminación",85%,IF(AJ14="Liberado",100%,IF(AJ14="N/A",100%,"ERROR")))))))) -> 0
A15: 12 | B15: 187 | C15: Central | D15: Atlacomulco Solar Fotovoltaica SA de CV | E15: Atlacomulco | F15: Estado de México | G15: Jocotitlán | H15: Fotovoltaica | I15: 100 | J15: SIN DATO | K15: SIN DATO | L15: SIN DATO | M15: SIN DATO | N15: SIN DATO | O15: SIN DATO | P15: SIN DATO | Q15: SIN DATO | R15: NoP | S15: Pendiente | T15: Pendiente | U15: Pendiente | V15: Pendiente | W15: Pendiente | X15: Pendiente | Y15: Pendiente | Z15: Pendiente | AA15: Pendiente | AB15: Pendiente | AC15: Pendiente | AD15: Pendiente | AE15: Pendiente | AF15: Pendiente | AG15: Pendiente | AH15: Pendiente | AI15: Pendiente | AJ15: Pendiente | AK15: =IF(S15="Pendiente",0%,IF(S15="En elaboración",20%,IF(S15="En evaluación",50%,IF(S15="Requerimiento",75%,IF(S15="En actualización",75%,IF(S15="En dictaminación",85%,IF(S15="Liberado",100%,IF(S15="N/A",100%,"ERROR")))))))) -> 0 | AL15: =IF(T15="Pendiente",0%,IF(T15="En elaboración",20%,IF(T15="En evaluación",50%,IF(T15="Requerimiento",75%,IF(T15="En actualización",75%,IF(T15="En dictaminación",85%,IF(T15="Liberado",100%,IF(T15="N/A",100%,"ERROR")))))))) -> 0 | AM15: =IF(U15="Pendiente",0%,IF(U15="En elaboración",20%,IF(U15="En evaluación",50%,IF(U15="Requerimiento",75%,IF(U15="En actualización",75%,IF(U15="En dictaminación",85%,IF(U15="Liberado",100%,IF(U15="N/A",100%,"ERROR")))))))) -> 0 | AN15: =IF(V15="Pendiente",0%,IF(V15="En elaboración",20%,IF(V15="En evaluación",50%,IF(V15="Requerimiento",75%,IF(V15="En actualización",75%,IF(V15="En dictaminación",85%,IF(V15="Liberado",100%,IF(V15="N/A",100%,"ERROR")))))))) -> 0 | AO15: =IF(W15="Pendiente",0%,IF(W15="En elaboración",20%,IF(W15="En evaluación",50%,IF(W15="Requerimiento",75%,IF(W15="En actualización",75%,IF(W15="En dictaminación",85%,IF(W15="Liberado",100%,IF(W15="N/A",100%,"ERROR")))))))) -> 0 | AP15: =IF(X15="Pendiente",0%,IF(X15="En elaboración",20%,IF(X15="En evaluación",50%,IF(X15="Requerimiento",75%,IF(X15="En actualización",75%,IF(X15="En dictaminación",85%,IF(X15="Liberado",100%,IF(X15="N/A",100%,"ERROR")))))))) -> 0 | AQ15: =IF(Y15="Pendiente",0%,IF(Y15="En elaboración",20%,IF(Y15="En evaluación",50%,IF(Y15="Requerimiento",75%,IF(Y15="En actualización",75%,IF(Y15="En dictaminación",85%,IF(Y15="Liberado",100%,IF(Y15="N/A",100%,"ERROR")))))))) -> 0 | AR15: =IF(Z15="Pendiente",0%,IF(Z15="En elaboración",20%,IF(Z15="En evaluación",50%,IF(Z15="Requerimiento",75%,IF(Z15="En actualización",75%,IF(Z15="En dictaminación",85%,IF(Z15="Liberado",100%,IF(Z15="N/A",100%,"ERROR")))))))) -> 0 | ... BB15: =IF(AJ15="Pendiente",0%,IF(AJ15="En elaboración",20%,IF(AJ15="En evaluación",50%,IF(AJ15="Requerimiento",75%,IF(AJ15="En actualización",75%,IF(AJ15="En dictaminación",85%,IF(AJ15="Liberado",100%,IF(AJ15="N/A",100%,"ERROR")))))))) -> 0
... A67: 64 | B67: 633 | C67: Oriental | D67: PV El Tintillo Solar SG S de RL de CV | E67: PV Tecamachalco Solar | F67: Puebla | G67: Tecamachalco | H67: Fotovoltaica | I67: 36 | J67: SIN DATO | K67: SIN DATO | L67: SIN DATO | M67: SIN DATO | N67: SIN DATO | O67: SIN DATO | P67: SIN DATO | Q67: SIN DATO | R67: NoP | S67: Pendiente | T67: Pendiente | U67: Pendiente | V67: Pendiente | W67: Pendiente | X67: Pendiente | Y67: Pendiente | Z67: Pendiente | AA67: Pendiente | AB67: Pendiente | AC67: Pendiente | AD67: Pendiente | AE67: Pendiente | AF67: Pendiente | AG67: Pendiente | AH67: Pendiente | AI67: Pendiente | AJ67: Pendiente | AK67: =IF(S67="Pendiente",0%,IF(S67="En elaboración",20%,IF(S67="En evaluación",50%,IF(S67="Requerimiento",75%,IF(S67="En actualización",75%,IF(S67="En dictaminación",85%,IF(S67="Liberado",100%,IF(S67="N/A",100%,"ERROR")))))))) -> 0 | AL67: =IF(T67="Pendiente",0%,IF(T67="En elaboración",20%,IF(T67="En evaluación",50%,IF(T67="Requerimiento",75%,IF(T67="En actualización",75%,IF(T67="En dictaminación",85%,IF(T67="Liberado",100%,IF(T67="N/A",100%,"ERROR")))))))) -> 0 | AM67: =IF(U67="Pendiente",0%,IF(U67="En elaboración",20%,IF(U67="En evaluación",50%,IF(U67="Requerimiento",75%,IF(U67="En actualización",75%,IF(U67="En dictaminación",85%,IF(U67="Liberado",100%,IF(U67="N/A",100%,"ERROR")))))))) -> 0 | AN67: =IF(V67="Pendiente",0%,IF(V67="En elaboración",20%,IF(V67="En evaluación",50%,IF(V67="Requerimiento",75%,IF(V67="En actualización",75%,IF(V67="En dictaminación",85%,IF(V67="Liberado",100%,IF(V67="N/A",100%,"ERROR")))))))) -> 0 | AO67: =IF(W67="Pendiente",0%,IF(W67="En elaboración",20%,IF(W67="En evaluación",50%,IF(W67="Requerimiento",75%,IF(W67="En actualización",75%,IF(W67="En dictaminación",85%,IF(W67="Liberado",100%,IF(W67="N/A",100%,"ERROR")))))))) -> 0 | AP67: =IF(X67="Pendiente",0%,IF(X67="En elaboración",20%,IF(X67="En evaluación",50%,IF(X67="Requerimiento",75%,IF(X67="En actualización",75%,IF(X67="En dictaminación",85%,IF(X67="Liberado",100%,IF(X67="N/A",100%,"ERROR")))))))) -> 0 | AQ67: =IF(Y67="Pendiente",0%,IF(Y67="En elaboración",20%,IF(Y67="En evaluación",50%,IF(Y67="Requerimiento",75%,IF(Y67="En actualización",75%,IF(Y67="En dictaminación",85%,IF(Y67="Liberado",100%,IF(Y67="N/A",100%,"ERROR")))))))) -> 0 | AR67: =IF(Z67="Pendiente",0%,IF(Z67="En elaboración",20%,IF(Z67="En evaluación",50%,IF(Z67="Requerimiento",75%,IF(Z67="En actualización",75%,IF(Z67="En dictaminación",85%,IF(Z67="Liberado",100%,IF(Z67="N/A",100%,"ERROR")))))))) -> 0 | ... BB67: =IF(AJ67="Pendiente",0%,IF(AJ67="En elaboración",20%,IF(AJ67="En evaluación",50%,IF(AJ67="Requerimiento",75%,IF(AJ67="En actualización",75%,IF(AJ67="En dictaminación",85%,IF(AJ67="Liberado",100%,IF(AJ67="N/A",100%,"ERROR")))))))) -> 0

Sheet REGLAS
A1: Color | B1: HEX | C1: Estatus | D1: Descripción | E1: Avance (%) | F1: Rango (%)
A2: Gris | B2: #BFBFBF | C2: Pendiente | D2: Trámite no iniciado o sin información por parte del socio. | E2: 0 | F2: 0<=x<20%
A3: Rojo | B3: #FF7C80 | C3: En elaboración | D3: El socio se encuentra integrando documentación y preparando el ingreso. | E3: 0.2 | F3: 20<=x<50%
A4: Amarillo | B4: #FFFF99 | C4: En evaluación | D4: Trámite ingresado ante la autoridad y en proceso de revisión. | E4: 0.5 | F4: 50<=x<75%
A5: Azul | B5: #95B3D7 | C5: Requerimiento | D5: La autoridad solicitó información adicional, aclaraciones, precisiones o se requiere una actualización derivada de cambios del socio. | E5: 0.75 | F5: 75<=x<85%
