Workbook

Sheet Resumen Ejecutivo
E2: =+'Base de Datos'!AB2 -> COMISIÓN FEDERAL DE ELECTRICIDAD | O2: Rev
E3: =+'Base de Datos'!AB3 -> COORDINACIÓN DE PROYECTOS DE ENERGÍAS LIMPIAS | O3: 3
E4: =+'Base de Datos'!AB4 -> GERENCIA DE CONSTRUCCIÓN | O4: =TODAY() -> 46325
E5: ESTADO DE TRÁMITES Y PERMISOS DE PROYECTOS MIXTOS, PRIMERA RONDA
C7: Socio | D7: Proyecto | E7: Municipio | F7: Estado | G7: Tipo | H7: Capacidad | I7: Fecha de inicio de inversión | J7: COD | K7: Avance en trámites y/o permisos | O7: Grupo de atención
K8: Parque | L8: LT | M8: Global
B9: 1 | C9: =+'Base de Datos'!C23 -> Cúbico | D9: =+'Base de Datos'!D23 -> Energías Renovables de Tamaulipas (Altamira) | E9: =+'Base de Datos'!E23 -> Altamira | F9: =+'Base de Datos'!F23 -> Tamaulipas | G9: =+'Base de Datos'!G23 -> Fotovoltaica | H9: =+'Base de Datos'!H23 -> 78 MW + 30% BESS | I9: =+'Base de Datos'!I23 -> 46388 | J9: =+'Base de Datos'!J23 -> 46935 | K9: =+'Base de Datos'!AD23 -> 0.94 | L9: =+'Base de Datos'!AE23 -> 0.93 | M9: =+'Base de Datos'!AG23 -> 0.938 | O9: =IF(K9>=85%,"A",IF(K9>=76%,"B","C")) -> A | R9: A | S9: =COUNTIFS($O$9:$O$48,R9) -> 7
B10: =1+B9 -> 2 | C10: =+'Base de Datos'!C34 -> Fisterra | D10: =+'Base de Datos'!D34 -> San Simón Solar | E10: =+'Base de Datos'!E34 -> San Quintín | F10: =+'Base de Datos'!F34 -> Baja California | G10: =+'Base de Datos'!G34 -> Fotovoltaica | H10: =+'Base de Datos'!H34 -> 80 MW + 30% BESS | I10: =+'Base de Datos'!I34 -> 46341 | J10: =+'Base de Datos'!J34 -> 47118 | K10: =+'Base de Datos'!AD34 -> 0.94 | L10: =+'Base de Datos'!AE34 -> 0.93 | M10: =+'Base de Datos'!AG34 -> 0.938 | O10: =IF(K10>=85%,"A",IF(K10>=76%,"B","C")) -> A | R10: B | S10: =COUNTIFS($O$9:$O$48,R10) -> 10
B11: =1+B10 -> 3 | C11: =+'Base de Datos'!C28 -> Elawan Wind Mexico III | D11: =+'Base de Datos'!D28 -> San Pedro Solar | E11: =+'Base de Datos'!E28 -> Huimalpan | F11: =+'Base de Datos'!F28 -> Querétaro | G11: =+'Base de Datos'!G28 -> Fotovoltaica | H11: =+'Base de Datos'!H28 -> 98.2 MW + 30% BESS | I11: =+'Base de Datos'!I28 -> 46447 | J11: =+'Base de Datos'!J28 -> 46843 | K11: =+'Base de Datos'!AD28 -> 0.915 | L11: =+'Base de Datos'!AE28 -> 0.86 | M11: =+'Base de Datos'!AG28 -> 0.904 | O11: =IF(K11>=85%,"A",IF(K11>=76%,"B","C")) -> A | R11: C | S11: =COUNTIFS($O$9:$O$48,R11) -> 23
B12: =1+B11 -> 4 | C12: =+'Base de Datos'!C14 -> Alten | D12: =+'Base de Datos'!D14 -> Global Solar 3 Campeche | E12: =+'Base de Datos'!E14 -> El Carmen | F12: =+'Base de Datos'!F14 -> Campeche | G12: =+'Base de Datos'!G14 -> Fotovoltaica | H12: =+'Base de Datos'!H14 -> 125 MW + 30.00% BESS | I12: =+'Base de Datos'!I14 -> 46388 | J12: =+'Base de Datos'!J14 -> 46935 | K12: =+'Base de Datos'!AD14 -> 0.875 | L12: =+'Base de Datos'!AE14 -> 0.8 | M12: =+'Base de Datos'!AG14 -> 0.86 | O12: =IF(K12>=85%,"A",IF(K12>=76%,"B","C")) -> A
B13: =1+B12 -> 5 | C13: =+'Base de Datos'!C42 -> Selka Power | D13: =+'Base de Datos'!D42 -> Selka Power Plant 1 | E13: =+'Base de Datos'!E42 -> Romita | F13: =+'Base de Datos'!F42 -> Guanajuato | G13: =+'Base de Datos'!G42 -> Fotovoltaica | H13: =+'Base de Datos'!H42 -> 141.4 MW + 30% BESS | I13: =+'Base de Datos'!I42 -> 46357 | J13: =+'Base de Datos'!J42 -> 46905 | K13: =+'Base de Datos'!AD42 -> 0.865 | L13: =+'Base de Datos'!AE42 -> 0.37 | M13: =+'Base de Datos'!AG42 -> 0.766 | O13: =IF(K13>=85%,"A",IF(K13>=76%,"B","C")) -> A
B14: =1+B13 -> 6 | C14: =+'Base de Datos'!C39 -> Polaris | D14: =+'Base de Datos'!D39 -> Don Humberto | E14: =+'Base de Datos'!E39 -> Culiacán | F14: =+'Base de Datos'!F39 -> Sinaloa | G14: =+'Base de Datos'!G39 -> Fotovoltaica | H14: =+'Base de Datos'!H39 -> 19.2 MW + 30% BESS | I14: =+'Base de Datos'!I39 -> 46327 | J14: =+'Base de Datos'!J39 -> 46844 | K14: =+'Base de Datos'!AD39 -> 0.86 | L14: =+'Base de Datos'!AE39 -> 0.77 | M14: =+'Base de Datos'!AG39 -> 0.842 | O14: =IF(K14>=85%,"A",IF(K14>=76%,"B","C")) -> A
B15: =1+B14 -> 7 | C15: =+'Base de Datos'!C47 -> Thermion | D15: =+'Base de Datos'!D47 -> Los Molinos | E15: =+'Base de Datos'!E47 -> Matamoros | F15: =+'Base de Datos'!F47 -> Tamaulipas | G15: =+'Base de Datos'!G47 -> Eólica | H15: =+'Base de Datos'!H47 -> 171 MW + 30% BESS | I15: =+'Base de Datos'!I47 -> 46371 | J15: =+'Base de Datos'!J47 -> 47088 | K15: =+'Base de Datos'!AD47 -> 0.855 | L15: =+'Base de Datos'!AE47 -> 0.855 | M15: =+'Base de Datos'!AG47 -> 0.855 | O15: =IF(K15>=85%,"A",IF(K15>=76%,"B","C")) -> A
B16: =1+B15 -> 8 | C16: =+'Base de Datos'!C32 -> Fisterra | D16: =+'Base de Datos'!D32 -> Haab Kiin | E16: =+'Base de Datos'!E32 -> Umán | F16: =+'Base de Datos'!F32 -> Yucatán | G16: =+'Base de Datos'!G32 -> Fotovoltaica | H16: =+'Base de Datos'!H32 -> 123.2 MW + 30% BESS | I16: =+'Base de Datos'!I32 -> 46356 | J16: =+'Base de Datos'!J32 -> 47208 | K16: =+'Base de Datos'!AD32 -> 0.84 | L16: =+'Base de Datos'!AE32 -> 0.735 | M16: =+'Base de Datos'!AG32 -> 0.819 | O16: =IF(K16>=85%,"A",IF(K16>=76%,"B","C")) -> B
B17: =1+B16 -> 9 | C17: =+'Base de Datos'!C17 -> Atlas Renewable Energy | D17: =+'Base de Datos'!D17 -> Concepción Mendizábal M. - Fase I | E17: =+'Base de Datos'!E17 -> Nava | F17: =+'Base de Datos'!F17 -> Coahuila | G17: =+'Base de Datos'!G17 -> Fotovoltaica | H17: =+'Base de Datos'!H17 -> 339 MW + 30.00% BESS | I17: =+'Base de Datos'!I17 -> 46478 | J17: =+'Base de Datos'!J17 -> 47209 | K17: =+'Base de Datos'!AD17 -> 0.8375 | L17: =+'Base de Datos'!AE17 -> 0.8375 | M17: =+'Base de Datos'!AG17 -> 0.8375 | O17: =IF(K17>=85%,"A",IF(K17>=76%,"B","C")) -> B
B18: =1+B17 -> 10 | C18: =+'Base de Datos'!C18 -> Atlas Renewable Energy | D18: =+'Base de Datos'!D18 -> Concepción Mendizábal M. - Fase II | E18: =+'Base de Datos'!E18 -> Nava | F18: =+'Base de Datos'!F18 -> Coahuila | G18: =+'Base de Datos'!G18 -> Fotovoltaica | H18: =+'Base de Datos'!H18 -> 180 MW + 30.00% BESS | I18: =+'Base de Datos'!I18 -> 46478 | J18: =+'Base de Datos'!J18 -> 47209 | K18: =+'Base de Datos'!AD18 -> 0.8375 | L18: =+'Base de Datos'!AE18 -> 0.8375 | M18: =+'Base de Datos'!AG18 -> 0.8375 | O18: =IF(K18>=85%,"A",IF(K18>=76%,"B","C")) -> B
B19: =1+B18 -> 11 | C19: =+'Base de Datos'!C45 -> Thermion | D19: =+'Base de Datos'!D45 -> Delaro (*) | E19: =+'Base de Datos'!E45 -> Reynosa | F19: =+'Base de Datos'!F45 -> Tamaulipas | G19: =+'Base de Datos'!G45 -> Eólica | H19: =+'Base de Datos'!H45 -> 117 MW + 30% BESS | I19: =+'Base de Datos'!I45 -> SIN DATO | J19: =+'Base de Datos'!J45 -> SIN DATO | K19: =+'Base de Datos'!AD45 -> 0.83 | L19: =+'Base de Datos'!AE45 -> 0.83 | M19: =+'Base de Datos'!AG45 -> 0.83 | O19: =IF(K19>=85%,"A",IF(K19>=76%,"B","C")) -> B
B20: =1+B19 -> 12 | C20: =+'Base de Datos'!C19 -> Atlas Renewable Energy | D20: =+'Base de Datos'!D19 -> Concepción Mendizábal M. - Fase III | E20: =+'Base de Datos'!E19 -> Nava | F20: =+'Base de Datos'!F19 -> Coahuila | G20: =+'Base de Datos'!G19 -> Fotovoltaica | H20: =+'Base de Datos'!H19 -> 339 MW + 30.00% BESS | I20: =+'Base de Datos'!I19 -> 46478 | J20: =+'Base de Datos'!J19 -> 47209 | K20: =+'Base de Datos'!AD19 -> 0.8275 | L20: =+'Base de Datos'!AE19 -> 0.8275 | M20: =+'Base de Datos'!AG19 -> 0.8275 | O20: =IF(K20>=85%,"A",IF(K20>=76%,"B","C")) -> B
B21: =1+B20 -> 13 | C21: =+'Base de Datos'!C37 -> Grupo ZML | D21: =+'Base de Datos'!D37 -> Álvaro Obregón | E21: =+'Base de Datos'!E37 -> La Paz | F21: =+'Base de Datos'!F37 -> Baja California Sur | G21: =+'Base de Datos'!G37 -> Fotovoltaica | H21: =+'Base de Datos'!H37 -> 90 MW + 100% BESS | I21: =+'Base de Datos'!I37 -> 46507 | J21: =+'Base de Datos'!J37 -> 47054 | K21: =+'Base de Datos'!AD37 -> 0.825 | L21: =+'Base de Datos'!AE37 -> 0.805 | M21: =+'Base de Datos'!AG37 -> 0.821 | O21: =IF(K21>=85%,"A",IF(K21>=76%,"B","C")) -> B
B22: =1+B21 -> 14 | C22: =+'Base de Datos'!C11 -> Actis | D22: =+'Base de Datos'!D11 -> PV Moquel Solar | E22: =+'Base de Datos'!E11 -> Champotón | F22: =+'Base de Datos'!F11 -> Campeche | G22: =+'Base de Datos'!G11 -> Fotovoltaica | H22: =+'Base de Datos'!H11 -> 75 MW + 34.08% BESS | I22: =+'Base de Datos'!I11 -> 46388 | J22: =+'Base de Datos'!J11 -> 46935 | K22: =+'Base de Datos'!AD11 -> 0.82 | L22: =+'Base de Datos'!AE11 -> 0.7 | M22: =+'Base de Datos'!AG11 -> 0.796 | O22: =IF(K22>=85%,"A",IF(K22>=76%,"B","C")) -> B
B23: =1+B22 -> 15 | C23: =+'Base de Datos'!C50 -> Thermion | D23: =+'Base de Datos'!D50 -> Sol de Sonora 70 | E23: =+'Base de Datos'!E50 -> Hermosillo | F23: =+'Base de Datos'!F50 -> Sonora | G23: =+'Base de Datos'!G50 -> Fotovoltaica | H23: =+'Base de Datos'!H50 -> 70 MW + 31.43% BESS | I23: =+'Base de Datos'!I50 -> 46357 | J23: =+'Base de Datos'!J50 -> 46844 | K23: =+'Base de Datos'!AD50 -> 0.82 | L23: =+'Base de Datos'!AE50 -> 0.82 | M23: =+'Base de Datos'!AG50 -> 0.82 | O23: =IF(K23>=85%,"A",IF(K23>=76%,"B","C")) -> B
B24: =1+B23 -> 16 | C24: =+'Base de Datos'!C12 -> Actis | D24: =+'Base de Datos'!D12 -> PV Sandom Solar | E24: =+'Base de Datos'!E12 -> Hopelchén | F24: =+'Base de Datos'!F12 -> Campeche | G24: =+'Base de Datos'!G12 -> Fotovoltaica | H24: =+'Base de Datos'!H12 -> 54 MW + 34.08% BESS | I24: =+'Base de Datos'!I12 -> 46478 | J24: =+'Base de Datos'!J12 -> 47057 | K24: =+'Base de Datos'!AD12 -> 0.8 | L24: =+'Base de Datos'!AE12 -> 0.555 | M24: =+'Base de Datos'!AG12 -> 0.751 | O24: =IF(K24>=85%,"A",IF(K24>=76%,"B","C")) -> B
B25: =1+B24 -> 17 | C25: =+'Base de Datos'!C15 -> Atlántica | D25: =+'Base de Datos'!D15 -> Dalia 3 (Castamay) | E25: =+'Base de Datos'!E15 -> Castamay | F25: =+'Base de Datos'!F15 -> Campeche | G25: =+'Base de Datos'!G15 -> Fotovoltaica | H25: =+'Base de Datos'!H15 -> 100 MW + 30% BESS | I25: =+'Base de Datos'!I15 -> 46447 | J25: =+'Base de Datos'!J15 -> 47118 | K25: =+'Base de Datos'!AD15 -> 0.79 | L25: =+'Base de Datos'!AE15 -> 0.535 | M25: =+'Base de Datos'!AG15 -> 0.739 | O25: =IF(K25>=85%,"A",IF(K25>=76%,"B","C")) -> B
B26: =1+B25 -> 18 | C26: =+'Base de Datos'!C24 -> Cúbico | D26: =+'Base de Datos'!D24 -> Energías Renovables De México Tres (Hecelchakan) | E26: =+'Base de Datos'!E24 -> Hecelchakán | F26: =+'Base de Datos'!F24 -> Campeche | G26: =+'Base de Datos'!G24 -> Fotovoltaica | H26: =+'Base de Datos'!H24 -> 72 MW + 30% BESS | I26: =+'Base de Datos'!I24 -> 46507 | J26: =+'Base de Datos'!J24 -> 47088 | K26: =+'Base de Datos'!AD24 -> 0.75 | L26: =+'Base de Datos'!AE24 -> 0.75 | M26: =+'Base de Datos'!AG24 -> 0.75 | O26: =IF(K26>=85%,"A",IF(K26>=76%,"B","C")) -> C
B27: =1+B26 -> 19 | C27: =+'Base de Datos'!C33 -> Fisterra | D27: =+'Base de Datos'!D33 -> Planta Solar Cerro Colorado | E27: =+'Base de Datos'!E33 -> Sayula de Alemán | F27: =+'Base de Datos'!F33 -> Veracruz | G27: =+'Base de Datos'!G33 -> Fotovoltaica | H27: =+'Base de Datos'!H33 -> 455.68 MW + 30% BESS | I27: =+'Base de Datos'!I33 -> 46356 | J27: =+'Base de Datos'!J33 -> 47360 | K27: =+'Base de Datos'!AD33 -> 0.75 | L27: =+'Base de Datos'!AE33 -> 0.585 | M27: =+'Base de Datos'!AG33 -> 0.717 | O27: =IF(K27>=85%,"A",IF(K27>=76%,"B","C")) -> C
B28: =1+B27 -> 20 | C28: =+'Base de Datos'!C26 -> Cúbico | D28: =+'Base de Datos'!D26 -> Energías Renovables Saas (Peto) | E28: =+'Base de Datos'!E26 -> Peto | F28: =+'Base de Datos'!F26 -> Yucatán | G28: =+'Base de Datos'!G26 -> Fotovoltaica | H28: =+'Base de Datos'!H26 -> 72 MW + 30% BESS | I28: =+'Base de Datos'!I26 -> 46507 | J28: =+'Base de Datos'!J26 -> 47058 | K28: =+'Base de Datos'!AD26 -> 0.74 | L28: =+'Base de Datos'!AE26 -> 0.64 | M28: =+'Base de Datos'!AG26 -> 0.72 | O28: =IF(K28>=85%,"A",IF(K28>=76%,"B","C")) -> C
B29: =1+B28 -> 21 | C29: =+'Base de Datos'!C27 -> Cúbico | D29: =+'Base de Datos'!D27 -> Energías Renovables Kiin (Tekax) | E29: =+'Base de Datos'!E27 -> Tekax | F29: =+'Base de Datos'!F27 -> Yucatán | G29: =+'Base de Datos'!G27 -> Fotovoltaica | H29: =+'Base de Datos'!H27 -> 56 MW + 30% BESS | I29: =+'Base de Datos'!I27 -> 46507 | J29: =+'Base de Datos'!J27 -> 47058 | K29: =+'Base de Datos'!AD27 -> 0.72 | L29: =+'Base de Datos'!AE27 -> 0.67 | M29: =+'Base de Datos'!AG27 -> 0.71 | O29: =IF(K29>=85%,"A",IF(K29>=76%,"B","C")) -> C
B30: =1+B29 -> 22 | C30: =+'Base de Datos'!C36 -> Grupo Pantera | D30: =+'Base de Datos'!D36 -> Solitario | E30: =+'Base de Datos'!E36 -> San Luis Río Colorado | F30: =+'Base de Datos'!F36 -> Sonora | G30: =+'Base de Datos'!G36 -> Fotovoltaica | H30: =+'Base de Datos'!H36 -> 200 MW + 32.5% BESS | I30: =+'Base de Datos'!I36 -> 46388 | J30: =+'Base de Datos'!J36 -> 47025 | K30: =+'Base de Datos'!AD36 -> 0.68 | L30: =+'Base de Datos'!AE36 -> 0.515 | M30: =+'Base de Datos'!AG36 -> 0.647 | O30: =IF(K30>=85%,"A",IF(K30>=76%,"B","C")) -> C
B31: =1+B30 -> 23 | C31: =+'Base de Datos'!C41 -> Polaris | D31: =+'Base de Datos'!D41 -> Tres Hermanos | E31: =+'Base de Datos'!E41 -> Huamantla / Xaloztoc | F31: =+'Base de Datos'!F41 -> Tlaxcala | G31: =+'Base de Datos'!G41 -> Fotovoltaica | H31: =+'Base de Datos'!H41 -> 75 MW + 30% BESS | I31: =+'Base de Datos'!I41 -> 46447 | J31: =+'Base de Datos'!J41 -> 47088 | K31: =+'Base de Datos'!AD41 -> 0.655 | L31: =+'Base de Datos'!AE41 -> 0.43 | M31: =+'Base de Datos'!AG41 -> 0.61 | O31: =IF(K31>=85%,"A",IF(K31>=76%,"B","C")) -> C
B32: =1+B31 -> 24 | C32: =+'Base de Datos'!C40 -> Polaris | D32: =+'Base de Datos'!D40 -> Los Girasoles | E32: =+'Base de Datos'!E40 -> José María Morelos | F32: =+'Base de Datos'!F40 -> Quintana Roo | G32: =+'Base de Datos'!G40 -> Fotovoltaica | H32: =+'Base de Datos'!H40 -> 110 MW + 30% BESS | I32: =+'Base de Datos'!I40 -> 46447 | J32: =+'Base de Datos'!J40 -> 47085 | K32: =+'Base de Datos'!AD40 -> 0.64 | L32: =+'Base de Datos'!AE40 -> 0.64 | M32: =+'Base de Datos'!AG40 -> 0.64 | O32: =IF(K32>=85%,"A",IF(K32>=76%,"B","C")) -> C
B33: =1+B32 -> 25 | C33: =+'Base de Datos'!C16 -> Atlántica | D33: =+'Base de Datos'!D16 -> Fresnillo (PV Atocha) | E33: =+'Base de Datos'!E16 -> Fresnillo | F33: =+'Base de Datos'!F16 -> Zacatecas | G33: =+'Base de Datos'!G16 -> Fotovoltaica | H33: =+'Base de Datos'!H16 -> 100 MW + 30% BESS | I33: =+'Base de Datos'!I16 -> 46447 | J33: =+'Base de Datos'!J16 -> 47118 | K33: =+'Base de Datos'!AD16 -> 0.625 | L33: =+'Base de Datos'!AE16 -> 0.41 | M33: =+'Base de Datos'!AG16 -> 0.582 | O33: =IF(K33>=85%,"A",IF(K33>=76%,"B","C")) -> C
B34: =1+B33 -> 26 | C34: =+'Base de Datos'!C13 -> Actis | D34: =+'Base de Datos'!D13 -> Viento de Bella Unión | E34: =+'Base de Datos'!E13 -> Arteaga | F34: =+'Base de Datos'!F13 -> Coahuila | G34: =+'Base de Datos'!G13 -> Fotovoltaica | H34: =+'Base de Datos'!H13 -> 120 MW + 34.08% BESS | I34: =+'Base de Datos'!I13 -> 46507 | J34: =+'Base de Datos'!J13 -> 47057 | K34: =+'Base de Datos'!AD13 -> 0.6 | L34: =+'Base de Datos'!AE13 -> 0.645 | M34: =+'Base de Datos'!AG13 -> 0.609 | O34: =IF(K34>=85%,"A",IF(K34>=76%,"B","C")) -> C
B35: =1+B34 -> 27 | C35: =+'Base de Datos'!C49 -> Thermion | D35: =+'Base de Datos'!D49 -> Santa Gertrudis | E35: =+'Base de Datos'!E49 -> Méndez | F35: =+'Base de Datos'!F49 -> Tamaulipas | G35: =+'Base de Datos'!G49 -> Eólica | H35: =+'Base de Datos'!H49 -> 503 MW + 30% BESS | I35: =+'Base de Datos'!I49 -> 46376 | J35: =+'Base de Datos'!J49 -> 47088 | K35: =+'Base de Datos'!AD49 -> 0.555 | L35: =+'Base de Datos'!AE49 -> 0.275 | M35: =+'Base de Datos'!AG49 -> 0.499 | O35: =IF(K35>=85%,"A",IF(K35>=76%,"B","C")) -> C
B36: =1+B35 -> 28 | C36: =+'Base de Datos'!C35 -> Grupo Pantera | D36: =+'Base de Datos'!D35 -> La Noria | E36: =+'Base de Datos'!E35 -> Villa Unión | F36: =+'Base de Datos'!F35 -> Coahuila | G36: =+'Base de Datos'!G35 -> Eólica | H36: =+'Base de Datos'!H35 -> 301.5 MW + 30% BESS | I36: =+'Base de Datos'!I35 -> 46478 | J36: =+'Base de Datos'!J35 -> 47209 | K36: =+'Base de Datos'!AD35 -> 0.54 | L36: =+'Base de Datos'!AE35 -> 0.44 | M36: =+'Base de Datos'!AG35 -> 0.52 | O36: =IF(K36>=85%,"A",IF(K36>=76%,"B","C")) -> C
B37: =1+B36 -> 29 | C37: =+'Base de Datos'!C22 -> CSQB Energy | D37: =+'Base de Datos'!D22 -> Sunora (**) | E37: =+'Base de Datos'!E22 -> Hermosillo | F37: =+'Base de Datos'!F22 -> Sonora | G37: =+'Base de Datos'!G22 -> Fotovoltaica | H37: =+'Base de Datos'!H22 -> 300 MW + 30% BESS | I37: =+'Base de Datos'!I22 -> 46507 | J37: =+'Base de Datos'!J22 -> 47238 | K37: =+'Base de Datos'!AD22 -> 0.49 | L37: =+'Base de Datos'!AE22 -> 0.54 | M37: =+'Base de Datos'!AG22 -> 0.5 | O37: =IF(K37>=85%,"A",IF(K37>=76%,"B","C")) -> C
B38: =1+B37 -> 30 | C38: =+'Base de Datos'!C48 -> Thermion | D38: =+'Base de Datos'!D48 -> Montecristo | E38: =+'Base de Datos'!E48 -> Méndez | F38: =+'Base de Datos'!F48 -> Tamaulipas | G38: =+'Base de Datos'!G48 -> Eólica | H38: =+'Base de Datos'!H48 -> 510 MW + 30% BESS | I38: =+'Base de Datos'!I48 -> 46376 | J38: =+'Base de Datos'!J48 -> 47088 | K38: =+'Base de Datos'!AD48 -> 0.44 | L38: =+'Base de Datos'!AE48 -> 0.25 | M38: =+'Base de Datos'!AG48 -> 0.402 | O38: =IF(K38>=85%,"A",IF(K38>=76%,"B","C")) -> C
B39: =1+B38 -> 31 | C39: =+'Base de Datos'!C38 -> MIP Freeman Energy | D39: =+'Base de Datos'!D38 -> CFV Las Garzas (**) | E39: =+'Base de Datos'!E38 -> Lerdo | F39: =+'Base de Datos'!F38 -> Durango | G39: =+'Base de Datos'!G38 -> Fotovoltaica | H39: =+'Base de Datos'!H38 -> 270 MW + 30% BESS | I39: =+'Base de Datos'!I38 -> 46477 | J39: =+'Base de Datos'!J38 -> 47302 | K39: =+'Base de Datos'!AD38 -> 0.44 | L39: =+'Base de Datos'!AE38 -> 0.255 | M39: =+'Base de Datos'!AG38 -> 0.403 | O39: =IF(K39>=85%,"A",IF(K39>=76%,"B","C")) -> C
B40: =1+B39 -> 32 | C40: =+'Base de Datos'!C25 -> Cúbico | D40: =+'Base de Datos'!D25 -> Energía Limpia el Mezquite | E40: =+'Base de Datos'!E25 -> Mina | F40: =+'Base de Datos'!F25 -> Nuevo León | G40: =+'Base de Datos'!G25 -> Eólica | H40: =+'Base de Datos'!H25 -> 300 MW + 30% BESS | I40: =+'Base de Datos'!I25 -> 46507 | J40: =+'Base de Datos'!J25 -> 47300 | K40: =+'Base de Datos'!AD25 -> 0.4 | L40: =+'Base de Datos'!AE25 -> 0.34 | M40: =+'Base de Datos'!AG25 -> 0.388 | O40: =IF(K40>=85%,"A",IF(K40>=76%,"B","C")) -> C
B41: =1+B40 -> 33 | C41: =+'Base de Datos'!C43 -> SuKarne | D41: =+'Base de Datos'!D43 -> CFV Quasara | E41: =+'Base de Datos'!E43 -> Mexicali | F41: =+'Base de Datos'!F43 -> Baja California | G41: =+'Base de Datos'!G43 -> Fotovoltaica | H41: =+'Base de Datos'!H43 -> 150 MW + 30% BESS | I41: =+'Base de Datos'!I43 -> 46447 | J41: =+'Base de Datos'!J43 -> 47119 | K41: =+'Base de Datos'!AD43 -> 0.355 | L41: =+'Base de Datos'!AE43 -> 0.35 | M41: =+'Base de Datos'!AG43 -> 0.354 | O41: =IF(K41>=85%,"A",IF(K41>=76%,"B","C")) -> C
B42: =1+B41 -> 34 | C42: =+'Base de Datos'!C21 -> CSQB Energy | D42: =+'Base de Datos'!D21 -> La Poza Solar (**) | E42: =+'Base de Datos'!E21 -> Hermosillo | F42: =+'Base de Datos'!F21 -> Sonora | G42: =+'Base de Datos'!G21 -> Fotovoltaica | H42: =+'Base de Datos'!H21 -> 300 MW + 30% BESS | I42: =+'Base de Datos'!I21 -> 46507 | J42: =+'Base de Datos'!J21 -> 47238 | K42: =+'Base de Datos'!AD21 -> 0.35 | L42: =+'Base de Datos'!AE21 -> 0.35 | M42: =+'Base de Datos'!AG21 -> 0.35 | O42: =IF(K42>=85%,"A",IF(K42>=76%,"B","C")) -> C
...

Sheet Proyectos ok
E2: =+'Base de Datos'!AB2 -> COMISIÓN FEDERAL DE ELECTRICIDAD | V2: Rev
E3: =+'Base de Datos'!AB3 -> COORDINACIÓN DE PROYECTOS DE ENERGÍAS LIMPIAS | V3: 3
E4: =+'Base de Datos'!AB4 -> GERENCIA DE CONSTRUCCIÓN | V4: =TODAY() -> 46325
E5: ESTADO DE TRÁMITES Y PERMISOS DE PROYECTOS MIXTOS, PRIMERA RONDA
C7: Socio | D7: Proyecto | E7: Municipio | F7: Estado | G7: Tipo | H7: Capacidad | I7: Fecha de Inicio de inversión | J7: COD | K7: Trámites y Permisos del Parque | V7: Grupo de Atención
K8: Derechos inmobiliarios | L8: Estudios Interconexión | M8: MIA / DTU | N8: ETJ | O8: MISSE / EVIS | P8: Consulta Indígena | Q8: PEMEX | R8: INAH | S8: CONAGUA | T8: AFAC
B9: 1 | C9: ='Resumen Ejecutivo'!C9 -> Cúbico | D9: ='Resumen Ejecutivo'!D9 -> Energías Renovables de Tamaulipas (Altamira) | E9: ='Resumen Ejecutivo'!E9 -> Altamira | F9: ='Resumen Ejecutivo'!F9 -> Tamaulipas | G9: ='Resumen Ejecutivo'!G9 -> Fotovoltaica | H9: ='Resumen Ejecutivo'!H9 -> 78 MW + 30% BESS | I9: ='Resumen Ejecutivo'!I9 -> 46388 | J9: ='Resumen Ejecutivo'!J9 -> 46935 | K9: =VLOOKUP(D9,CAPEX!$E$2:$BQ$41,48,FALSE) -> Liberado | L9: =VLOOKUP(D9,CAPEX!$E$2:$BQ$41,50,FALSE) -> Liberado | M9: =VLOOKUP(D9,CAPEX!$E$2:$BQ$41,51,FALSE) -> Liberado | N9: =VLOOKUP(D9,CAPEX!$E$2:$BQ$41,53,FALSE) -> En evaluación | O9: =VLOOKUP(D9,CAPEX!$E$2:$BQ$41,55,FALSE) -> Liberado | P9: =VLOOKUP(D9,CAPEX!$E$2:$BQ$41,57,FALSE) -> N/A | Q9: =VLOOKUP(D9,CAPEX!$E$2:$BQ$41,60,FALSE) -> En evaluación | R9: =VLOOKUP(D9,CAPEX!$E$2:$BQ$41,58,FALSE) -> Liberado | S9: =VLOOKUP(D9,CAPEX!$E$2:$BQ$41,62,FALSE) -> Liberado | T9: =VLOOKUP(D9,CAPEX!$E$2:$BQ$41,64,FALSE) -> En elaboración | V9: ='Resumen Ejecutivo'!O9 -> A | Y9: A | Z9: ='Resumen Ejecutivo'!S9 -> 7
B10: 2 | C10: ='Resumen Ejecutivo'!C10 -> Fisterra | D10: ='Resumen Ejecutivo'!D10 -> San Simón Solar | E10: San Quintin | F10: Baja California | G10: Fotovoltaico | H10: ='Resumen Ejecutivo'!H10 -> 80 MW + 30% BESS | I10: ='Resumen Ejecutivo'!I10 -> 46341 | J10: ='Resumen Ejecutivo'!J10 -> 47118 | K10: =VLOOKUP(D10,CAPEX!$E$2:$BQ$41,48,FALSE) -> Liberado | L10: =VLOOKUP(D10,CAPEX!$E$2:$BQ$41,50,FALSE) -> Liberado | M10: =VLOOKUP(D10,CAPEX!$E$2:$BQ$41,51,FALSE) -> Liberado | N10: =VLOOKUP(D10,CAPEX!$E$2:$BQ$41,53,FALSE) -> N/A | O10: =VLOOKUP(D10,CAPEX!$E$2:$BQ$41,55,FALSE) -> Liberado | P10: =VLOOKUP(D10,CAPEX!$E$2:$BQ$41,57,FALSE) -> N/A | Q10: =VLOOKUP(D10,CAPEX!$E$2:$BQ$41,60,FALSE) -> En evaluación | R10: =VLOOKUP(D10,CAPEX!$E$2:$BQ$41,58,FALSE) -> Liberado | S10: =VLOOKUP(D10,CAPEX!$E$2:$BQ$41,62,FALSE) -> Liberado | T10: =VLOOKUP(D10,CAPEX!$E$2:$BQ$41,64,FALSE) -> En evaluación | V10: ='Resumen Ejecutivo'!O10 -> A | Y10: B | Z10: ='Resumen Ejecutivo'!S10 -> 10
B11: 3 | C11: ='Resumen Ejecutivo'!C11 -> Elawan Wind Mexico III | D11: ='Resumen Ejecutivo'!D11 -> San Pedro Solar | E11: Huimilpan y Corregidora | F11: Querétaro | G11: Fotovoltaico | H11: ='Resumen Ejecutivo'!H11 -> 98.2 MW + 30% BESS | I11: ='Resumen Ejecutivo'!I11 -> 46447 | J11: ='Resumen Ejecutivo'!J11 -> 46843 | K11: =VLOOKUP(D11,CAPEX!$E$2:$BQ$41,48,FALSE) -> En actualización | L11: =VLOOKUP(D11,CAPEX!$E$2:$BQ$41,50,FALSE) -> Liberado | M11: =VLOOKUP(D11,CAPEX!$E$2:$BQ$41,51,FALSE) -> En evaluación | N11: =VLOOKUP(D11,CAPEX!$E$2:$BQ$41,53,FALSE) -> N/A | O11: =VLOOKUP(D11,CAPEX!$E$2:$BQ$41,55,FALSE) -> En evaluación | P11: =VLOOKUP(D11,CAPEX!$E$2:$BQ$41,57,FALSE) -> N/A | Q11: =VLOOKUP(D11,CAPEX!$E$2:$BQ$41,60,FALSE) -> Liberado | R11: =VLOOKUP(D11,CAPEX!$E$2:$BQ$41,58,FALSE) -> Liberado | S11: =VLOOKUP(D11,CAPEX!$E$2:$BQ$41,62,FALSE) -> En evaluación | T11: =VLOOKUP(D11,CAPEX!$E$2:$BQ$41,64,FALSE) -> En evaluación | V11: ='Resumen Ejecutivo'!O11 -> A | Y11: C | Z11: ='Resumen Ejecutivo'!S11 -> 23
B12: 4 | C12: ='Resumen Ejecutivo'!C12 -> Alten | D12: ='Resumen Ejecutivo'!D12 -> Global Solar 3 Campeche | E12: El Carmen | F12: Campeche | G12: Fotovoltaico | H12: ='Resumen Ejecutivo'!H12 -> 125 MW + 30.00% BESS | I12: ='Resumen Ejecutivo'!I12 -> 46388 | J12: ='Resumen Ejecutivo'!J12 -> 46935 | K12: =VLOOKUP(D12,CAPEX!$E$2:$BQ$41,48,FALSE) -> Liberado | L12: =VLOOKUP(D12,CAPEX!$E$2:$BQ$41,50,FALSE) -> Liberado | M12: =VLOOKUP(D12,CAPEX!$E$2:$BQ$41,51,FALSE) -> En evaluación | N12: =VLOOKUP(D12,CAPEX!$E$2:$BQ$41,53,FALSE) -> En evaluación | O12: =VLOOKUP(D12,CAPEX!$E$2:$BQ$41,55,FALSE) -> Liberado | P12: =VLOOKUP(D12,CAPEX!$E$2:$BQ$41,57,FALSE) -> Iniciada | Q12: =VLOOKUP(D12,CAPEX!$E$2:$BQ$41,60,FALSE) -> Liberado | R12: =VLOOKUP(D12,CAPEX!$E$2:$BQ$41,58,FALSE) -> En evaluación | S12: =VLOOKUP(D12,CAPEX!$E$2:$BQ$41,62,FALSE) -> Liberado | T12: =VLOOKUP(D12,CAPEX!$E$2:$BQ$41,64,FALSE) -> En evaluación | V12: ='Resumen Ejecutivo'!O12 -> A
B13: 5 | C13: ='Resumen Ejecutivo'!C13 -> Selka Power | D13: ='Resumen Ejecutivo'!D13 -> Selka Power Plant 1 | E13: Romita | F13: Guanajuato | G13: Fotovoltaico | H13: ='Resumen Ejecutivo'!H13 -> 141.4 MW + 30% BESS | I13: ='Resumen Ejecutivo'!I13 -> 46357 | J13: ='Resumen Ejecutivo'!J13 -> 46905 | K13: =VLOOKUP(D13,CAPEX!$E$2:$BQ$41,48,FALSE) -> En actualización | L13: =VLOOKUP(D13,CAPEX!$E$2:$BQ$41,50,FALSE) -> Liberado | M13: =VLOOKUP(D13,CAPEX!$E$2:$BQ$41,51,FALSE) -> En evaluación | N13: =VLOOKUP(D13,CAPEX!$E$2:$BQ$41,53,FALSE) -> N/A | O13: =VLOOKUP(D13,CAPEX!$E$2:$BQ$41,55,FALSE) -> En evaluación | P13: =VLOOKUP(D13,CAPEX!$E$2:$BQ$41,57,FALSE) -> N/A | Q13: =VLOOKUP(D13,CAPEX!$E$2:$BQ$41,60,FALSE) -> Liberado | R13: =VLOOKUP(D13,CAPEX!$E$2:$BQ$41,58,FALSE) -> Liberado | S13: =VLOOKUP(D13,CAPEX!$E$2:$BQ$41,62,FALSE) -> En evaluación | T13: =VLOOKUP(D13,CAPEX!$E$2:$BQ$41,64,FALSE) -> En elaboración | V13: ='Resumen Ejecutivo'!O13 -> A
B14: 6 | C14: ='Resumen Ejecutivo'!C14 -> Polaris | D14: ='Resumen Ejecutivo'!D14 -> Don Humberto | E14: Culiacán | F14: Sinaloa | G14: Fotovoltaico | H14: ='Resumen Ejecutivo'!H14 -> 19.2 MW + 30% BESS | I14: ='Resumen Ejecutivo'!I14 -> 46327 | J14: ='Resumen Ejecutivo'!J14 -> 46844 | K14: =VLOOKUP(D14,CAPEX!$E$2:$BQ$41,48,FALSE) -> En actualización | L14: =VLOOKUP(D14,CAPEX!$E$2:$BQ$41,50,FALSE) -> Liberado | M14: =VLOOKUP(D14,CAPEX!$E$2:$BQ$41,51,FALSE) -> En evaluación | N14: =VLOOKUP(D14,CAPEX!$E$2:$BQ$41,53,FALSE) -> N/A | O14: =VLOOKUP(D14,CAPEX!$E$2:$BQ$41,55,FALSE) -> Liberado | P14: =VLOOKUP(D14,CAPEX!$E$2:$BQ$41,57,FALSE) -> N/A | Q14: =VLOOKUP(D14,CAPEX!$E$2:$BQ$41,60,FALSE) -> Liberado | R14: =VLOOKUP(D14,CAPEX!$E$2:$BQ$41,58,FALSE) -> En actualización | S14: =VLOOKUP(D14,CAPEX!$E$2:$BQ$41,62,FALSE) -> En elaboración | T14: =VLOOKUP(D14,CAPEX!$E$2:$BQ$41,64,FALSE) -> En evaluación | V14: ='Resumen Ejecutivo'!O14 -> A
B15: 7 | C15: ='Resumen Ejecutivo'!C15 -> Thermion | D15: ='Resumen Ejecutivo'!D15 -> Los Molinos | E15: Matamoros | F15: Tamaulipas | G15: Eólico | H15: ='Resumen Ejecutivo'!H15 -> 171 MW + 30% BESS | I15: ='Resumen Ejecutivo'!I15 -> 46371 | J15: ='Resumen Ejecutivo'!J15 -> 47088 | K15: =VLOOKUP(D15,CAPEX!$E$2:$BQ$41,48,FALSE) -> Liberado | L15: =VLOOKUP(D15,CAPEX!$E$2:$BQ$41,50,FALSE) -> En actualización | M15: =VLOOKUP(D15,CAPEX!$E$2:$BQ$41,51,FALSE) -> En actualización | N15: =VLOOKUP(D15,CAPEX!$E$2:$BQ$41,53,FALSE) -> En evaluación | O15: =VLOOKUP(D15,CAPEX!$E$2:$BQ$41,55,FALSE) -> En elaboración | P15: =VLOOKUP(D15,CAPEX!$E$2:$BQ$41,57,FALSE) -> N/A | Q15: =VLOOKUP(D15,CAPEX!$E$2:$BQ$41,60,FALSE) -> Liberado | R15: =VLOOKUP(D15,CAPEX!$E$2:$BQ$41,58,FALSE) -> En evaluación | S15: =VLOOKUP(D15,CAPEX!$E$2:$BQ$41,62,FALSE) -> En evaluación | T15: =VLOOKUP(D15,CAPEX!$E$2:$BQ$41,64,FALSE) -> En evaluación | V15: ='Resumen Ejecutivo'!O15 -> A
B16: 8 | C16: ='Resumen Ejecutivo'!C16 -> Fisterra | D16: ='Resumen Ejecutivo'!D16 -> Haab Kiin | E16: Úman | F16: Yucatán | G16: Fotovoltaico | H16: ='Resumen Ejecutivo'!H16 -> 123.2 MW + 30% BESS | I16: ='Resumen Ejecutivo'!I16 -> 46356 | J16: ='Resumen Ejecutivo'!J16 -> 47208 | K16: =VLOOKUP(D16,CAPEX!$E$2:$BQ$41,48,FALSE) -> Liberado | L16: =VLOOKUP(D16,CAPEX!$E$2:$BQ$41,50,FALSE) -> Liberado | M16: =VLOOKUP(D16,CAPEX!$E$2:$BQ$41,51,FALSE) -> En evaluación | N16: =VLOOKUP(D16,CAPEX!$E$2:$BQ$41,53,FALSE) -> En elaboración | O16: =VLOOKUP(D16,CAPEX!$E$2:$BQ$41,55,FALSE) -> Liberado | P16: =VLOOKUP(D16,CAPEX!$E$2:$BQ$41,57,FALSE) -> Iniciada | Q16: =VLOOKUP(D16,CAPEX!$E$2:$BQ$41,60,FALSE) -> Liberado | R16: =VLOOKUP(D16,CAPEX!$E$2:$BQ$41,58,FALSE) -> En evaluación | S16: =VLOOKUP(D16,CAPEX!$E$2:$BQ$41,62,FALSE) -> Liberado | T16: =VLOOKUP(D16,CAPEX!$E$2:$BQ$41,64,FALSE) -> Liberado | V16: ='Resumen Ejecutivo'!O16 -> B
B17: 9 | C17: ='Resumen Ejecutivo'!C17 -> Atlas Renewable Energy | D17: ='Resumen Ejecutivo'!D17 -> Concepción Mendizábal M. - Fase I | E17: Nava | F17: Coahuila | G17: Fotovoltaico | H17: ='Resumen Ejecutivo'!H17 -> 339 MW + 30.00% BESS | I17: ='Resumen Ejecutivo'!I17 -> 46478 | J17: ='Resumen Ejecutivo'!J17 -> 47209 | K17: =VLOOKUP(D17,CAPEX!$E$2:$BQ$41,48,FALSE) -> Liberado | L17: =VLOOKUP(D17,CAPEX!$E$2:$BQ$41,50,FALSE) -> En actualización | M17: =VLOOKUP(D17,CAPEX!$E$2:$BQ$41,51,FALSE) -> En evaluación | N17: =VLOOKUP(D17,CAPEX!$E$2:$BQ$41,53,FALSE) -> N/A | O17: =VLOOKUP(D17,CAPEX!$E$2:$BQ$41,55,FALSE) -> Liberado | P17: =VLOOKUP(D17,CAPEX!$E$2:$BQ$41,57,FALSE) -> N/A | Q17: =VLOOKUP(D17,CAPEX!$E$2:$BQ$41,60,FALSE) -> En elaboración | R17: =VLOOKUP(D17,CAPEX!$E$2:$BQ$41,58,FALSE) -> Liberado | S17: =VLOOKUP(D17,CAPEX!$E$2:$BQ$41,62,FALSE) -> En evaluación | T17: =VLOOKUP(D17,CAPEX!$E$2:$BQ$41,64,FALSE) -> En elaboración | V17: ='Resumen Ejecutivo'!O17 -> B
B18: 10 | C18: ='Resumen Ejecutivo'!C18 -> Atlas Renewable Energy | D18: ='Resumen Ejecutivo'!D18 -> Concepción Mendizábal M. - Fase II | E18: Nava | F18: Coahuila | G18: Fotovoltaico | H18: ='Resumen Ejecutivo'!H18 -> 180 MW + 30.00% BESS | I18: ='Resumen Ejecutivo'!I18 -> 46478 | J18: ='Resumen Ejecutivo'!J18 -> 47209 | K18: =VLOOKUP(D18,CAPEX!$E$2:$BQ$41,48,FALSE) -> Liberado | L18: =VLOOKUP(D18,CAPEX!$E$2:$BQ$41,50,FALSE) -> En actualización | M18: =VLOOKUP(D18,CAPEX!$E$2:$BQ$41,51,FALSE) -> En evaluación | N18: =VLOOKUP(D18,CAPEX!$E$2:$BQ$41,53,FALSE) -> N/A | O18: =VLOOKUP(D18,CAPEX!$E$2:$BQ$41,55,FALSE) -> Liberado | P18: =VLOOKUP(D18,CAPEX!$E$2:$BQ$41,57,FALSE) -> N/A | Q18: =VLOOKUP(D18,CAPEX!$E$2:$BQ$41,60,FALSE) -> En elaboración | R18: =VLOOKUP(D18,CAPEX!$E$2:$BQ$41,58,FALSE) -> Liberado | S18: =VLOOKUP(D18,CAPEX!$E$2:$BQ$41,62,FALSE) -> En evaluación | T18: =VLOOKUP(D18,CAPEX!$E$2:$BQ$41,64,FALSE) -> En elaboración | V18: ='Resumen Ejecutivo'!O18 -> B
B19: 11 | C19: ='Resumen Ejecutivo'!C19 -> Thermion | D19: ='Resumen Ejecutivo'!D19 -> Delaro (*) | E19: Reynosa | F19: Tamaulipas | G19: Eólico | H19: ='Resumen Ejecutivo'!H19 -> 117 MW + 30% BESS | I19: ='Resumen Ejecutivo'!I19 -> SIN DATO | J19: ='Resumen Ejecutivo'!J19 -> SIN DATO | K19: =VLOOKUP(D19,CAPEX!$E$2:$BQ$41,48,FALSE) -> Liberado | L19: =VLOOKUP(D19,CAPEX!$E$2:$BQ$41,50,FALSE) -> En actualización | M19: =VLOOKUP(D19,CAPEX!$E$2:$BQ$41,51,FALSE) -> En elaboración | N19: =VLOOKUP(D19,CAPEX!$E$2:$BQ$41,53,FALSE) -> N/A | O19: =VLOOKUP(D19,CAPEX!$E$2:$BQ$41,55,FALSE) -> En actualización | P19: =VLOOKUP(D19,CAPEX!$E$2:$BQ$41,57,FALSE) -> N/A | Q19: =VLOOKUP(D19,CAPEX!$E$2:$BQ$41,60,FALSE) -> En evaluación | R19: =VLOOKUP(D19,CAPEX!$E$2:$BQ$41,58,FALSE) -> En actualización | S19: =VLOOKUP(D19,CAPEX!$E$2:$BQ$41,62,FALSE) -> En evaluación | T19: =VLOOKUP(D19,CAPEX!$E$2:$BQ$41,64,FALSE) -> En elaboración | V19: ='Resumen Ejecutivo'!O19 -> B
B20: 12 | C20: ='Resumen Ejecutivo'!C20 -> Atlas Renewable Energy | D20: ='Resumen Ejecutivo'!D20 -> Concepción Mendizábal M. - Fase III | E20: Nava | F20: Coahuila | G20: Fotovoltaico | H20: ='Resumen Ejecutivo'!H20 -> 339 MW + 30.00% BESS | I20: ='Resumen Ejecutivo'!I20 -> 46478 | J20: ='Resumen Ejecutivo'!J20 -> 47209 | K20: =VLOOKUP(D20,CAPEX!$E$2:$BQ$41,48,FALSE) -> Liberado | L20: =VLOOKUP(D20,CAPEX!$E$2:$BQ$41,50,FALSE) -> En actualización | M20: =VLOOKUP(D20,CAPEX!$E$2:$BQ$41,51,FALSE) -> En actualización | N20: =VLOOKUP(D20,CAPEX!$E$2:$BQ$41,53,FALSE) -> En evaluación | O20: =VLOOKUP(D20,CAPEX!$E$2:$BQ$41,55,FALSE) -> Liberado | P20: =VLOOKUP(D20,CAPEX!$E$2:$BQ$41,57,FALSE) -> N/A | Q20: =VLOOKUP(D20,CAPEX!$E$2:$BQ$41,60,FALSE) -> En elaboración | R20: =VLOOKUP(D20,CAPEX!$E$2:$BQ$41,58,FALSE) -> Liberado | S20: =VLOOKUP(D20,CAPEX!$E$2:$BQ$41,62,FALSE) -> N/A | T20: =VLOOKUP(D20,CAPEX!$E$2:$BQ$41,64,FALSE) -> En elaboración | V20: ='Resumen Ejecutivo'!O20 -> B
B21: 13 | C21: ='Resumen Ejecutivo'!C21 -> Grupo ZML | D21: ='Resumen Ejecutivo'!D21 -> Álvaro Obregón | E21: La Paz | F21: Baja California Sur | G21: Fotovoltaico | H21: ='Resumen Ejecutivo'!H21 -> 90 MW + 100% BESS | I21: ='Resumen Ejecutivo'!I21 -> 46507 | J21: ='Resumen Ejecutivo'!J21 -> 47054 | K21: =VLOOKUP(D21,CAPEX!$E$2:$BQ$41,48,FALSE) -> Liberado | L21: =VLOOKUP(D21,CAPEX!$E$2:$BQ$41,50,FALSE) -> Liberado | M21: =VLOOKUP(D21,CAPEX!$E$2:$BQ$41,51,FALSE) -> En evaluación | N21: =VLOOKUP(D21,CAPEX!$E$2:$BQ$41,53,FALSE) -> En elaboración | O21: =VLOOKUP(D21,CAPEX!$E$2:$BQ$41,55,FALSE) -> En actualización | P21: =VLOOKUP(D21,CAPEX!$E$2:$BQ$41,57,FALSE) -> N/A | Q21: =VLOOKUP(D21,CAPEX!$E$2:$BQ$41,60,FALSE) -> Liberado | R21: =VLOOKUP(D21,CAPEX!$E$2:$BQ$41,58,FALSE) -> En evaluación | S21: =VLOOKUP(D21,CAPEX!$E$2:$BQ$41,62,FALSE) -> En evaluación | T21: =VLOOKUP(D21,CAPEX!$E$2:$BQ$41,64,FALSE) -> Liberado | V21: ='Resumen Ejecutivo'!O21 -> B
B22: 14 | C22: ='Resumen Ejecutivo'!C22 -> Actis | D22: ='Resumen Ejecutivo'!D22 -> PV Moquel Solar | E22: Champotón | F22: Campeche | G22: Fotovoltaico | H22: ='Resumen Ejecutivo'!H22 -> 75 MW + 34.08% BESS | I22: ='Resumen Ejecutivo'!I22 -> 46388 | J22: ='Resumen Ejecutivo'!J22 -> 46935 | K22: =VLOOKUP(D22,CAPEX!$E$2:$BQ$41,48,FALSE) -> Liberado | L22: =VLOOKUP(D22,CAPEX!$E$2:$BQ$41,50,FALSE) -> Liberado | M22: =VLOOKUP(D22,CAPEX!$E$2:$BQ$41,51,FALSE) -> En actualización | N22: =VLOOKUP(D22,CAPEX!$E$2:$BQ$41,53,FALSE) -> En elaboración | O22: =VLOOKUP(D22,CAPEX!$E$2:$BQ$41,55,FALSE) -> Liberado | P22: =VLOOKUP(D22,CAPEX!$E$2:$BQ$41,57,FALSE) -> Iniciada | Q22: =VLOOKUP(D22,CAPEX!$E$2:$BQ$41,60,FALSE) -> Liberado | R22: =VLOOKUP(D22,CAPEX!$E$2:$BQ$41,58,FALSE) -> En actualización | S22: =VLOOKUP(D22,CAPEX!$E$2:$BQ$41,62,FALSE) -> Liberado | T22: =VLOOKUP(D22,CAPEX!$E$2:$BQ$41,64,FALSE) -> En evaluación | V22: ='Resumen Ejecutivo'!O22 -> B
B23: 15 | C23: ='Resumen Ejecutivo'!C23 -> Thermion | D23: ='Resumen Ejecutivo'!D23 -> Sol de Sonora 70 | E23: Hermosillo | F23: Sonora | G23: Fotovoltaico | H23: ='Resumen Ejecutivo'!H23 -> 70 MW + 31.43% BESS | I23: ='Resumen Ejecutivo'!I23 -> 46357 | J23: ='Resumen Ejecutivo'!J23 -> 46844 | K23: =VLOOKUP(D23,CAPEX!$E$2:$BQ$41,48,FALSE) -> Liberado | L23: =VLOOKUP(D23,CAPEX!$E$2:$BQ$41,50,FALSE) -> Liberado | M23: =VLOOKUP(D23,CAPEX!$E$2:$BQ$41,51,FALSE) -> En actualización | N23: =VLOOKUP(D23,CAPEX!$E$2:$BQ$41,53,FALSE) -> En elaboración | O23: =VLOOKUP(D23,CAPEX!$E$2:$BQ$41,55,FALSE) -> En actualización | P23: =VLOOKUP(D23,CAPEX!$E$2:$BQ$41,57,FALSE) -> N/A | Q23: =VLOOKUP(D23,CAPEX!$E$2:$BQ$41,60,FALSE) -> En evaluación | R23: =VLOOKUP(D23,CAPEX!$E$2:$BQ$41,58,FALSE) -> En actualización | S23: =VLOOKUP(D23,CAPEX!$E$2:$BQ$41,62,FALSE) -> En evaluación | T23: =VLOOKUP(D23,CAPEX!$E$2:$BQ$41,64,FALSE) -> En evaluación | V23: ='Resumen Ejecutivo'!O23 -> B
... B25: 17 | C25: ='Resumen Ejecutivo'!C25 -> Atlántica | D25: ='Resumen Ejecutivo'!D25 -> Dalia 3 (Castamay) | E25: Campeche | F25: Campeche | G25: Fotovoltaico | H25: ='Resumen Ejecutivo'!H25 -> 100 MW + 30% BESS | I25: ='Resumen Ejecutivo'!I25 -> 46447 | J25: ='Resumen Ejecutivo'!J25 -> 47118 | K25: =VLOOKUP(D25,CAPEX!$E$2:$BQ$41,48,FALSE) -> En actualización | L25: =VLOOKUP(D25,CAPEX!$E$2:$BQ$41,50,FALSE) -> Liberado | M25: =VLOOKUP(D25,CAPEX!$E$2:$BQ$41,51,FALSE) -> En evaluación | N25: =VLOOKUP(D25,CAPEX!$E$2:$BQ$41,53,FALSE) -> En elaboración | O25: =VLOOKUP(D25,CAPEX!$E$2:$BQ$41,55,FALSE) -> En evaluación | P25: =VLOOKUP(D25,CAPEX!$E$2:$BQ$41,57,FALSE) -> Iniciada | Q25: =VLOOKUP(D25,CAPEX!$E$2:$BQ$41,60,FALSE) -> Liberado | R25: =VLOOKUP(D25,CAPEX!$E$2:$BQ$41,58,FALSE) -> Liberado | S25: =VLOOKUP(D25,CAPEX!$E$2:$BQ$41,62,FALSE) -> Liberado | T25: =VLOOKUP(D25,CAPEX!$E$2:$BQ$41,64,FALSE) -> Liberado | V25: ='Resumen Ejecutivo'!O25 -> B
B26: 18 | C26: ='Resumen Ejecutivo'!C26 -> Cúbico | D26: ='Resumen Ejecutivo'!D26 -> Energías Renovables De México Tres (Hecelchakan) | E26: ='Resumen Ejecutivo'!E26 -> Hecelchakán | F26: ='Resumen Ejecutivo'!F26 -> Campeche | G26: ='Resumen Ejecutivo'!G26 -> Fotovoltaica | H26: ='Resumen Ejecutivo'!H26 -> 72 MW + 30% BESS | I26: ='Resumen Ejecutivo'!I26 -> 46507 | J26: ='Resumen Ejecutivo'!J26 -> 47088 | K26: =VLOOKUP(D26,CAPEX!$E$2:$BQ$41,48,FALSE) -> 0 | L26: =VLOOKUP(D26,CAPEX!$E$2:$BQ$41,50,FALSE) -> 0 | M26: =VLOOKUP(D26,CAPEX!$E$2:$BQ$41,51,FALSE) -> 0 | N26: =VLOOKUP(D26,CAPEX!$E$2:$BQ$41,53,FALSE) -> 0 | O26: =VLOOKUP(D26,CAPEX!$E$2:$BQ$41,55,FALSE) -> 0 | P26: =VLOOKUP(D26,CAPEX!$E$2:$BQ$41,57,FALSE) -> 0 | Q26: =VLOOKUP(D26,CAPEX!$E$2:$BQ$41,60,FALSE) -> 0 | R26: =VLOOKUP(D26,CAPEX!$E$2:$BQ$41,58,FALSE) -> 0 | S26: =VLOOKUP(D26,CAPEX!$E$2:$BQ$41,62,FALSE) -> 0 | T26: =VLOOKUP(D26,CAPEX!$E$2:$BQ$41,64,FALSE) -> 0 | V26: ='Resumen Ejecutivo'!O26 -> C
B27: 19 | C27: ='Resumen Ejecutivo'!C27 -> Fisterra | D27: ='Resumen Ejecutivo'!D27 -> Planta Solar Cerro Colorado | E27: San Quintin | F27: Baja California | G27: Fotovoltaico | H27: ='Resumen Ejecutivo'!H27 -> 455.68 MW + 30% BESS | I27: ='Resumen Ejecutivo'!I27 -> 46356 | J27: ='Resumen Ejecutivo'!J27 -> 47360 | K27: =VLOOKUP(D27,CAPEX!$E$2:$BQ$41,48,FALSE) -> 0 | L27: =VLOOKUP(D27,CAPEX!$E$2:$BQ$41,50,FALSE) -> 0 | M27: =VLOOKUP(D27,CAPEX!$E$2:$BQ$41,51,FALSE) -> 0 | N27: =VLOOKUP(D27,CAPEX!$E$2:$BQ$41,53,FALSE) -> 0 | O27: =VLOOKUP(D27,CAPEX!$E$2:$BQ$41,55,FALSE) -> 0 | P27: =VLOOKUP(D27,CAPEX!$E$2:$BQ$41,57,FALSE) -> 0 | Q27: =VLOOKUP(D27,CAPEX!$E$2:$BQ$41,60,FALSE) -> 0 | R27: =VLOOKUP(D27,CAPEX!$E$2:$BQ$41,58,FALSE) -> 0 | S27: =VLOOKUP(D27,CAPEX!$E$2:$BQ$41,62,FALSE) -> 0 | T27: =VLOOKUP(D27,CAPEX!$E$2:$BQ$41,64,FALSE) -> 0 | V27: ='Resumen Ejecutivo'!O27 -> C
B28: 20 | C28: ='Resumen Ejecutivo'!C28 -> Cúbico | D28: ='Resumen Ejecutivo'!D28 -> Energías Renovables Saas (Peto) | E28: Huimilpan y Corregidora | F28: Querétaro | G28: Fotovoltaico | H28: ='Resumen Ejecutivo'!H28 -> 72 MW + 30% BESS | I28: ='Resumen Ejecutivo'!I28 -> 46507 | J28: ='Resumen Ejecutivo'!J28 -> 47058 | K28: =VLOOKUP(D28,CAPEX!$E$2:$BQ$41,48,FALSE) -> 0 | L28: =VLOOKUP(D28,CAPEX!$E$2:$BQ$41,50,FALSE) -> 0 | M28: =VLOOKUP(D28,CAPEX!$E$2:$BQ$41,51,FALSE) -> 0 | N28: =VLOOKUP(D28,CAPEX!$E$2:$BQ$41,53,FALSE) -> 0 | O28: =VLOOKUP(D28,CAPEX!$E$2:$BQ$41,55,FALSE) -> 0 | P28: =VLOOKUP(D28,CAPEX!$E$2:$BQ$41,57,FALSE) -> 0 | Q28: =VLOOKUP(D28,CAPEX!$E$2:$BQ$41,60,FALSE) -> 0 | R28: =VLOOKUP(D28,CAPEX!$E$2:$BQ$41,58,FALSE) -> 0 | S28: =VLOOKUP(D28,CAPEX!$E$2:$BQ$41,62,FALSE) -> 0 | T28: =VLOOKUP(D28,CAPEX!$E$2:$BQ$41,64,FALSE) -> 0 | V28: ='Resumen Ejecutivo'!O28 -> C
B29: 21 | C29: ='Resumen Ejecutivo'!C29 -> Cúbico | D29: ='Resumen Ejecutivo'!D29 -> Energías Renovables Kiin (Tekax) | E29: El Carmen | F29: Campeche | G29: Fotovoltaico | H29: ='Resumen Ejecutivo'!H29 -> 56 MW + 30% BESS | I29: ='Resumen Ejecutivo'!I29 -> 46507 | J29: ='Resumen Ejecutivo'!J29 -> 47058 | K29: =VLOOKUP(D29,CAPEX!$E$2:$BQ$41,48,FALSE) -> 0 | L29: =VLOOKUP(D29,CAPEX!$E$2:$BQ$41,50,FALSE) -> 0 | M29: =VLOOKUP(D29,CAPEX!$E$2:$BQ$41,51,FALSE) -> 0 | N29: =VLOOKUP(D29,CAPEX!$E$2:$BQ$41,53,FALSE) -> 0 | O29: =VLOOKUP(D29,CAPEX!$E$2:$BQ$41,55,FALSE) -> 0 | P29: =VLOOKUP(D29,CAPEX!$E$2:$BQ$41,57,FALSE) -> 0 | Q29: =VLOOKUP(D29,CAPEX!$E$2:$BQ$41,60,FALSE) -> 0 | R29: =VLOOKUP(D29,CAPEX!$E$2:$BQ$41,58,FALSE) -> 0 | S29: =VLOOKUP(D29,CAPEX!$E$2:$BQ$41,62,FALSE) -> 0 | T29: =VLOOKUP(D29,CAPEX!$E$2:$BQ$41,64,FALSE) -> 0 | V29: ='Resumen Ejecutivo'!O29 -> C
B30: 22 | C30: ='Resumen Ejecutivo'!C30 -> Grupo Pantera | D30: ='Resumen Ejecutivo'!D30 -> Solitario | E30: Romita | F30: Guanajuato | G30: Fotovoltaico | H30: ='Resumen Ejecutivo'!H30 -> 200 MW + 32.5% BESS | I30: ='Resumen Ejecutivo'!I30 -> 46388 | J30: ='Resumen Ejecutivo'!J30 -> 47025 | K30: =VLOOKUP(D30,CAPEX!$E$2:$BQ$41,48,FALSE) -> 0 | L30: =VLOOKUP(D30,CAPEX!$E$2:$BQ$41,50,FALSE) -> 0 | M30: =VLOOKUP(D30,CAPEX!$E$2:$BQ$41,51,FALSE) -> 0 | N30: =VLOOKUP(D30,CAPEX!$E$2:$BQ$41,53,FALSE) -> 0 | O30: =VLOOKUP(D30,CAPEX!$E$2:$BQ$41,55,FALSE) -> 0 | P30: =VLOOKUP(D30,CAPEX!$E$2:$BQ$41,57,FALSE) -> 0 | Q30: =VLOOKUP(D30,CAPEX!$E$2:$BQ$41,60,FALSE) -> 0 | R30: =VLOOKUP(D30,CAPEX!$E$2:$BQ$41,58,FALSE) -> 0 | S30: =VLOOKUP(D30,CAPEX!$E$2:$BQ$41,62,FALSE) -> 0 | T30: =VLOOKUP(D30,CAPEX!$E$2:$BQ$41,64,FALSE) -> 0 | V30: ='Resumen Ejecutivo'!O30 -> C
B31: 23 | C31: ='Resumen Ejecutivo'!C31 -> Polaris | D31: ='Resumen Ejecutivo'!D31 -> Tres Hermanos | E31: Culiacán | F31: Sinaloa | G31: Fotovoltaico | H31: ='Resumen Ejecutivo'!H31 -> 75 MW + 30% BESS | I31: ='Resumen Ejecutivo'!I31 -> 46447 | J31: ='Resumen Ejecutivo'!J31 -> 47088 | K31: =VLOOKUP(D31,CAPEX!$E$2:$BQ$41,48,FALSE) -> 0 | L31: =VLOOKUP(D31,CAPEX!$E$2:$BQ$41,50,FALSE) -> 0 | M31: =VLOOKUP(D31,CAPEX!$E$2:$BQ$41,51,FALSE) -> 0 | N31: =VLOOKUP(D31,CAPEX!$E$2:$BQ$41,53,FALSE) -> 0 | O31: =VLOOKUP(D31,CAPEX!$E$2:$BQ$41,55,FALSE) -> 0 | P31: =VLOOKUP(D31,CAPEX!$E$2:$BQ$41,57,FALSE) -> 0 | Q31: =VLOOKUP(D31,CAPEX!$E$2:$BQ$41,60,FALSE) -> 0 | R31: =VLOOKUP(D31,CAPEX!$E$2:$BQ$41,58,FALSE) -> 0 | S31: =VLOOKUP(D31,CAPEX!$E$2:$BQ$41,62,FALSE) -> 0 | T31: =VLOOKUP(D31,CAPEX!$E$2:$BQ$41,64,FALSE) -> 0 | V31: ='Resumen Ejecutivo'!O31 -> C
B32: 24 | C32: ='Resumen Ejecutivo'!C32 -> Polaris | D32: ='Resumen Ejecutivo'!D32 -> Los Girasoles | E32: Matamoros | F32: Tamaulipas | G32: Eólico | H32: ='Resumen Ejecutivo'!H32 -> 110 MW + 30% BESS | I32: ='Resumen Ejecutivo'!I32 -> 46447 | J32: ='Resumen Ejecutivo'!J32 -> 47085 | K32: =VLOOKUP(D32,CAPEX!$E$2:$BQ$41,48,FALSE) -> 0 | L32: =VLOOKUP(D32,CAPEX!$E$2:$BQ$41,50,FALSE) -> 0 | M32: =VLOOKUP(D32,CAPEX!$E$2:$BQ$41,51,FALSE) -> 0 | N32: =VLOOKUP(D32,CAPEX!$E$2:$BQ$41,53,FALSE) -> 0 | O32: =VLOOKUP(D32,CAPEX!$E$2:$BQ$41,55,FALSE) -> 0 | P32: =VLOOKUP(D32,CAPEX!$E$2:$BQ$41,57,FALSE) -> 0 | Q32: =VLOOKUP(D32,CAPEX!$E$2:$BQ$41,60,FALSE) -> 0 | R32: =VLOOKUP(D32,CAPEX!$E$2:$BQ$41,58,FALSE) -> 0 | S32: =VLOOKUP(D32,CAPEX!$E$2:$BQ$41,62,FALSE) -> 0 | T32: =VLOOKUP(D32,CAPEX!$E$2:$BQ$41,64,FALSE) -> 0 | V32: ='Resumen Ejecutivo'!O32 -> C
B33: 25 | C33: ='Resumen Ejecutivo'!C33 -> Atlántica | D33: ='Resumen Ejecutivo'!D33 -> Fresnillo (PV Atocha) | E33: Úman | F33: Yucatán | G33: Fotovoltaico | H33: ='Resumen Ejecutivo'!H33 -> 100 MW + 30% BESS | I33: ='Resumen Ejecutivo'!I33 -> 46447 | J33: ='Resumen Ejecutivo'!J33 -> 47118 | K33: =VLOOKUP(D33,CAPEX!$E$2:$BQ$41,48,FALSE) -> 0 | L33: =VLOOKUP(D33,CAPEX!$E$2:$BQ$41,50,FALSE) -> 0 | M33: =VLOOKUP(D33,CAPEX!$E$2:$BQ$41,51,FALSE) -> 0 | N33: =VLOOKUP(D33,CAPEX!$E$2:$BQ$41,53,FALSE) -> 0 | O33: =VLOOKUP(D33,CAPEX!$E$2:$BQ$41,55,FALSE) -> 0 | P33: =VLOOKUP(D33,CAPEX!$E$2:$BQ$41,57,FALSE) -> 0 | Q33: =VLOOKUP(D33,CAPEX!$E$2:$BQ$41,60,FALSE) -> 0 | R33: =VLOOKUP(D33,CAPEX!$E$2:$BQ$41,58,FALSE) -> 0 | S33: =VLOOKUP(D33,CAPEX!$E$2:$BQ$41,62,FALSE) -> 0 | T33: =VLOOKUP(D33,CAPEX!$E$2:$BQ$41,64,FALSE) -> 0 | V33: ='Resumen Ejecutivo'!O33 -> C
B34: 26 | C34: ='Resumen Ejecutivo'!C34 -> Actis | D34: ='Resumen Ejecutivo'!D34 -> Viento de Bella Unión | E34: Nava | F34: Coahuila | G34: Fotovoltaico | H34: ='Resumen Ejecutivo'!H34 -> 120 MW + 34.08% BESS | I34: ='Resumen Ejecutivo'!I34 -> 46507 | J34: ='Resumen Ejecutivo'!J34 -> 47057 | K34: =VLOOKUP(D34,CAPEX!$E$2:$BQ$41,48,FALSE) -> 0 | L34: =VLOOKUP(D34,CAPEX!$E$2:$BQ$41,50,FALSE) -> 0 | M34: =VLOOKUP(D34,CAPEX!$E$2:$BQ$41,51,FALSE) -> 0 | N34: =VLOOKUP(D34,CAPEX!$E$2:$BQ$41,53,FALSE) -> 0 | O34: =VLOOKUP(D34,CAPEX!$E$2:$BQ$41,55,FALSE) -> 0 | P34: =VLOOKUP(D34,CAPEX!$E$2:$BQ$41,57,FALSE) -> 0 | Q34: =VLOOKUP(D34,CAPEX!$E$2:$BQ$41,60,FALSE) -> 0 | R34: =VLOOKUP(D34,CAPEX!$E$2:$BQ$41,58,FALSE) -> 0 | S34: =VLOOKUP(D34,CAPEX!$E$2:$BQ$41,62,FALSE) -> 0 | T34: =VLOOKUP(D34,CAPEX!$E$2:$BQ$41,64,FALSE) -> 0 | V34: ='Resumen Ejecutivo'!O34 -> C
B35: 27 | C35: ='Resumen Ejecutivo'!C35 -> Thermion | D35: ='Resumen Ejecutivo'!D35 -> Santa Gertrudis | E35: Nava | F35: Coahuila | G35: Fotovoltaico | H35: ='Resumen Ejecutivo'!H35 -> 503 MW + 30% BESS | I35: ='Resumen Ejecutivo'!I35 -> 46376 | J35: ='Resumen Ejecutivo'!J35 -> 47088 | K35: =VLOOKUP(D35,CAPEX!$E$2:$BQ$41,48,FALSE) -> 0 | L35: =VLOOKUP(D35,CAPEX!$E$2:$BQ$41,50,FALSE) -> 0 | M35: =VLOOKUP(D35,CAPEX!$E$2:$BQ$41,51,FALSE) -> 0 | N35: =VLOOKUP(D35,CAPEX!$E$2:$BQ$41,53,FALSE) -> 0 | O35: =VLOOKUP(D35,CAPEX!$E$2:$BQ$41,55,FALSE) -> 0 | P35: =VLOOKUP(D35,CAPEX!$E$2:$BQ$41,57,FALSE) -> 0 | Q35: =VLOOKUP(D35,CAPEX!$E$2:$BQ$41,60,FALSE) -> 0 | R35: =VLOOKUP(D35,CAPEX!$E$2:$BQ$41,58,FALSE) -> 0 | S35: =VLOOKUP(D35,CAPEX!$E$2:$BQ$41,62,FALSE) -> 0 | T35: =VLOOKUP(D35,CAPEX!$E$2:$BQ$41,64,FALSE) -> 0 | V35: ='Resumen Ejecutivo'!O35 -> C
B36: 28 | C36: ='Resumen Ejecutivo'!C36 -> Grupo Pantera | D36: ='Resumen Ejecutivo'!D36 -> La Noria | E36: Reynosa | F36: Tamaulipas | G36: Eólico | H36: ='Resumen Ejecutivo'!H36 -> 301.5 MW + 30% BESS | I36: ='Resumen Ejecutivo'!I36 -> 46478 | J36: ='Resumen Ejecutivo'!J36 -> 47209 | K36: =VLOOKUP(D36,CAPEX!$E$2:$BQ$41,48,FALSE) -> 0 | L36: =VLOOKUP(D36,CAPEX!$E$2:$BQ$41,50,FALSE) -> 0 | M36: =VLOOKUP(D36,CAPEX!$E$2:$BQ$41,51,FALSE) -> 0 | N36: =VLOOKUP(D36,CAPEX!$E$2:$BQ$41,53,FALSE) -> 0 | O36: =VLOOKUP(D36,CAPEX!$E$2:$BQ$41,55,FALSE) -> 0 | P36: =VLOOKUP(D36,CAPEX!$E$2:$BQ$41,57,FALSE) -> 0 | Q36: =VLOOKUP(D36,CAPEX!$E$2:$BQ$41,60,FALSE) -> 0 | R36: =VLOOKUP(D36,CAPEX!$E$2:$BQ$41,58,FALSE) -> 0 | S36: =VLOOKUP(D36,CAPEX!$E$2:$BQ$41,62,FALSE) -> 0 | T36: =VLOOKUP(D36,CAPEX!$E$2:$BQ$41,64,FALSE) -> 0 | V36: ='Resumen Ejecutivo'!O36 -> C
B37: 29 | C37: ='Resumen Ejecutivo'!C37 -> CSQB Energy | D37: ='Resumen Ejecutivo'!D37 -> Sunora (**) | E37: Nava | F37: Coahuila | G37: Fotovoltaico | H37: ='Resumen Ejecutivo'!H37 -> 300 MW + 30% BESS | I37: ='Resumen Ejecutivo'!I37 -> 46507 | J37: ='Resumen Ejecutivo'!J37 -> 47238 | K37: =VLOOKUP(D37,CAPEX!$E$2:$BQ$41,48,FALSE) -> 0 | L37: =VLOOKUP(D37,CAPEX!$E$2:$BQ$41,50,FALSE) -> 0 | M37: =VLOOKUP(D37,CAPEX!$E$2:$BQ$41,51,FALSE) -> 0 | N37: =VLOOKUP(D37,CAPEX!$E$2:$BQ$41,53,FALSE) -> 0 | O37: =VLOOKUP(D37,CAPEX!$E$2:$BQ$41,55,FALSE) -> 0 | P37: =VLOOKUP(D37,CAPEX!$E$2:$BQ$41,57,FALSE) -> 0 | Q37: =VLOOKUP(D37,CAPEX!$E$2:$BQ$41,60,FALSE) -> 0 | R37: =VLOOKUP(D37,CAPEX!$E$2:$BQ$41,58,FALSE) -> 0 | S37: =VLOOKUP(D37,CAPEX!$E$2:$BQ$41,62,FALSE) -> 0 | T37: =VLOOKUP(D37,CAPEX!$E$2:$BQ$41,64,FALSE) -> 0 | V37: ='Resumen Ejecutivo'!O37 -> C
B38: 30 | C38: ='Resumen Ejecutivo'!C38 -> Thermion | D38: ='Resumen Ejecutivo'!D38 -> Montecristo | E38: La Paz | F38: Baja California Sur | G38: Fotovoltaico | H38: ='Resumen Ejecutivo'!H38 -> 510 MW + 30% BESS | I38: ='Resumen Ejecutivo'!I38 -> 46376 | J38: ='Resumen Ejecutivo'!J38 -> 47088 | K38: =VLOOKUP(D38,CAPEX!$E$2:$BQ$41,48,FALSE) -> 0 | L38: =VLOOKUP(D38,CAPEX!$E$2:$BQ$41,50,FALSE) -> 0 | M38: =VLOOKUP(D38,CAPEX!$E$2:$BQ$41,51,FALSE) -> 0 | N38: =VLOOKUP(D38,CAPEX!$E$2:$BQ$41,53,FALSE) -> 0 | O38: =VLOOKUP(D38,CAPEX!$E$2:$BQ$41,55,FALSE) -> 0 | P38: =VLOOKUP(D38,CAPEX!$E$2:$BQ$41,57,FALSE) -> 0 | Q38: =VLOOKUP(D38,CAPEX!$E$2:$BQ$41,60,FALSE) -> 0 | R38: =VLOOKUP(D38,CAPEX!$E$2:$BQ$41,58,FALSE) -> 0 | S38: =VLOOKUP(D38,CAPEX!$E$2:$BQ$41,62,FALSE) -> 0 | T38: =VLOOKUP(D38,CAPEX!$E$2:$BQ$41,64,FALSE) -> 0 | V38: ='Resumen Ejecutivo'!O38 -> C
... B42: 34 | C42: ='Resumen Ejecutivo'!C42 -> CSQB Energy | D42: ='Resumen Ejecutivo'!D42 -> La Poza Solar (**) | E42: Campeche | F42: Campeche | G42: Fotovoltaico | H42: ='Resumen Ejecutivo'!H42 -> 300 MW + 30% BESS | I42: ='Resumen Ejecutivo'!I42 -> 46507 | J42: ='Resumen Ejecutivo'!J42 -> 47238 | K42: =VLOOKUP(D42,CAPEX!$E$2:$BQ$41,48,FALSE) -> 0 | L42: =VLOOKUP(D42,CAPEX!$E$2:$BQ$41,50,FALSE) -> 0 | M42: =VLOOKUP(D42,CAPEX!$E$2:$BQ$41,51,FALSE) -> 0 | N42: =VLOOKUP(D42,CAPEX!$E$2:$BQ$41,53,FALSE) -> 0 | O42: =VLOOKUP(D42,CAPEX!$E$2:$BQ$41,55,FALSE) -> 0 | P42: =VLOOKUP(D42,CAPEX!$E$2:$BQ$41,57,FALSE) -> 0 | Q42: =VLOOKUP(D42,CAPEX!$E$2:$BQ$41,60,FALSE) -> 0 | R42: =VLOOKUP(D42,CAPEX!$E$2:$BQ$41,58,FALSE) -> 0 | S42: =VLOOKUP(D42,CAPEX!$E$2:$BQ$41,62,FALSE) -> 0 | T42: =VLOOKUP(D42,CAPEX!$E$2:$BQ$41,64,FALSE) -> 0 | V42: ='Resumen Ejecutivo'!O42 -> C
B43: 35 | C43: ='Resumen Ejecutivo'!C43 -> CSQB Energy | D43: ='Resumen Ejecutivo'!D43 -> Cimarrón Solar (**) | E43: ='Resumen Ejecutivo'!E43 -> Hermosillo | F43: ='Resumen Ejecutivo'!F43 -> Sonora | G43: ='Resumen Ejecutivo'!G43 -> Fotovoltaica | H43: ='Resumen Ejecutivo'!H43 -> 300 MW + 30% BESS | I43: ='Resumen Ejecutivo'!I43 -> 46507 | J43: ='Resumen Ejecutivo'!J43 -> 47238 | K43: =VLOOKUP(D43,CAPEX!$E$2:$BQ$41,48,FALSE) -> 0 | L43: =VLOOKUP(D43,CAPEX!$E$2:$BQ$41,50,FALSE) -> 0 | M43: =VLOOKUP(D43,CAPEX!$E$2:$BQ$41,51,FALSE) -> 0 | N43: =VLOOKUP(D43,CAPEX!$E$2:$BQ$41,53,FALSE) -> 0 | O43: =VLOOKUP(D43,CAPEX!$E$2:$BQ$41,55,FALSE) -> 0 | P43: =VLOOKUP(D43,CAPEX!$E$2:$BQ$41,57,FALSE) -> 0 | Q43: =VLOOKUP(D43,CAPEX!$E$2:$BQ$41,60,FALSE) -> 0 | R43: =VLOOKUP(D43,CAPEX!$E$2:$BQ$41,58,FALSE) -> 0 | S43: =VLOOKUP(D43,CAPEX!$E$2:$BQ$41,62,FALSE) -> 0 | T43: =VLOOKUP(D43,CAPEX!$E$2:$BQ$41,64,FALSE) -> 0 | V43: ='Resumen Ejecutivo'!O43 -> C
B44: 36 | C44: ='Resumen Ejecutivo'!C44 -> Thermion | D44: ='Resumen Ejecutivo'!D44 -> El Guajillo | E44: San Quintin | F44: Baja California | G44: Fotovoltaico | H44: ='Resumen Ejecutivo'!H44 -> 468 MW + 30% BESS | I44: ='Resumen Ejecutivo'!I44 -> 46376 | J44: ='Resumen Ejecutivo'!J44 -> 47088 | K44: =VLOOKUP(D44,CAPEX!$E$2:$BQ$41,48,FALSE) -> 0 | L44: =VLOOKUP(D44,CAPEX!$E$2:$BQ$41,50,FALSE) -> 0 | M44: =VLOOKUP(D44,CAPEX!$E$2:$BQ$41,51,FALSE) -> 0 | N44: =VLOOKUP(D44,CAPEX!$E$2:$BQ$41,53,FALSE) -> 0 | O44: =VLOOKUP(D44,CAPEX!$E$2:$BQ$41,55,FALSE) -> 0 | P44: =VLOOKUP(D44,CAPEX!$E$2:$BQ$41,57,FALSE) -> 0 | Q44: =VLOOKUP(D44,CAPEX!$E$2:$BQ$41,60,FALSE) -> 0 | R44: =VLOOKUP(D44,CAPEX!$E$2:$BQ$41,58,FALSE) -> 0 | S44: =VLOOKUP(D44,CAPEX!$E$2:$BQ$41,62,FALSE) -> 0 | T44: =VLOOKUP(D44,CAPEX!$E$2:$BQ$41,64,FALSE) -> 0 | V44: ='Resumen Ejecutivo'!O44 -> C
B45: 37 | C45: ='Resumen Ejecutivo'!C45 -> Eléctrica Aselco | D45: ='Resumen Ejecutivo'!D45 -> El Palmar | E45: Huimilpan y Corregidora | F45: Querétaro | G45: Fotovoltaico | H45: ='Resumen Ejecutivo'!H45 -> 120 MW + 30% BESS | I45: ='Resumen Ejecutivo'!I45 -> 46452 | J45: ='Resumen Ejecutivo'!J45 -> 47238 | K45: =VLOOKUP(D45,CAPEX!$E$2:$BQ$41,48,FALSE) -> 0 | L45: =VLOOKUP(D45,CAPEX!$E$2:$BQ$41,50,FALSE) -> 0 | M45: =VLOOKUP(D45,CAPEX!$E$2:$BQ$41,51,FALSE) -> 0 | N45: =VLOOKUP(D45,CAPEX!$E$2:$BQ$41,53,FALSE) -> 0 | O45: =VLOOKUP(D45,CAPEX!$E$2:$BQ$41,55,FALSE) -> 0 | P45: =VLOOKUP(D45,CAPEX!$E$2:$BQ$41,57,FALSE) -> 0 | Q45: =VLOOKUP(D45,CAPEX!$E$2:$BQ$41,60,FALSE) -> 0 | R45: =VLOOKUP(D45,CAPEX!$E$2:$BQ$41,58,FALSE) -> 0 | S45: =VLOOKUP(D45,CAPEX!$E$2:$BQ$41,62,FALSE) -> 0 | T45: =VLOOKUP(D45,CAPEX!$E$2:$BQ$41,64,FALSE) -> 0 | V45: ='Resumen Ejecutivo'!O45 -> C
B46: 38 | C46: ='Resumen Ejecutivo'!C46 -> Eléctrica Aselco | D46: ='Resumen Ejecutivo'!D46 -> Tikinmul | E46: El Carmen | F46: Campeche | G46: Fotovoltaico | H46: ='Resumen Ejecutivo'!H46 -> 170 MW + 30% BESS | I46: ='Resumen Ejecutivo'!I46 -> 46461 | J46: ='Resumen Ejecutivo'!J46 -> 47238 | K46: =VLOOKUP(D46,CAPEX!$E$2:$BQ$41,48,FALSE) -> 0 | L46: =VLOOKUP(D46,CAPEX!$E$2:$BQ$41,50,FALSE) -> 0 | M46: =VLOOKUP(D46,CAPEX!$E$2:$BQ$41,51,FALSE) -> 0 | N46: =VLOOKUP(D46,CAPEX!$E$2:$BQ$41,53,FALSE) -> 0 | O46: =VLOOKUP(D46,CAPEX!$E$2:$BQ$41,55,FALSE) -> 0 | P46: =VLOOKUP(D46,CAPEX!$E$2:$BQ$41,57,FALSE) -> 0 | Q46: =VLOOKUP(D46,CAPEX!$E$2:$BQ$41,60,FALSE) -> 0 | R46: =VLOOKUP(D46,CAPEX!$E$2:$BQ$41,58,FALSE) -> 0 | S46: =VLOOKUP(D46,CAPEX!$E$2:$BQ$41,62,FALSE) -> 0 | T46: =VLOOKUP(D46,CAPEX!$E$2:$BQ$41,64,FALSE) -> 0 | V46: ='Resumen Ejecutivo'!O46 -> C
...

Sheet Base de Datos
AB2: COMISIÓN FEDERAL DE ELECTRICIDAD | AD2: Rev 3 | AG2: =TODAY() -> 46325
AB3: COORDINACIÓN DE PROYECTOS DE ENERGÍAS LIMPIAS
AB4: GERENCIA DE CONSTRUCCIÓN
G5: ESTADO DE TRÁMITES Y PERMISOS DE PROYECTOS MIXTOS, PRIMERA RONDA
B8: No. | C8: Socio | D8: Proyecto | E8: Municipio | F8: Ubicación | G8: Tecnología | H8: Capacidad | I8: Fecha de Incio de invesión | J8: COD | K8: Derechos Inmobiliarios | M8: Estudios de interconexión | N8: Ambientales | R8: Social | U8: Dependencias | AD8: Avance Tratimtes Parque | AE8: Avance Tramites Línea | AG8: Avance Trámites Proyecto
N9: MIA - DTU | P9: ETJ | R9: MISSE (EvIS) | T9: Consulta Indígena | U9: INAH | W9: PEMEX | Y9: CONAGUA | AA9: AFAC
K10: Parque | L10: LT | N10: Parque | O10: LT | P10: Parque | Q10: LT | R10: Parque | S10: LT | U10: Parque | V10: LT | W10: Parque | X10: LT | Y10: Parque | Z10: LT | AA10: Parque | AB10: LT
B11: 1 | C11: =CAPEX!F2 -> Actis | D11: =CAPEX!E2 -> PV Moquel Solar | E11: =CAPEX!AD2 -> Champotón | F11: =CAPEX!AC2 -> Campeche | G11: =CAPEX!G2 -> Fotovoltaica | H11: =CAPEX!K2 -> 75 MW + 34.08% BESS | I11: =CAPEX!M2 -> 46388 | J11: =CAPEX!N2 -> 46935 | K11: =CAPEX!AH2 -> 1 | L11: =CAPEX!AI2 -> 0.5 | M11: =CAPEX!AJ2 -> 1 | N11: =CAPEX!AK2 -> 0.8 | O11: =CAPEX!AL2 -> 0.5 | P11: =CAPEX!AM2 -> 0.5 | Q11: =CAPEX!AN2 -> 0.5 | R11: =CAPEX!AO2 -> 1 | ... AB11: =CAPEX!AY2 -> 0.9 | AD11: =CAPEX!AE2 -> 0.82 | AE11: =CAPEX!AF2 -> 0.7 | AG11: =CAPEX!AG2 -> 0.796
B12: 2 | C12: =CAPEX!F3 -> Actis | D12: =CAPEX!E3 -> PV Sandom Solar | E12: =CAPEX!AD3 -> Hopelchén | F12: =CAPEX!AC3 -> Campeche | G12: =CAPEX!G3 -> Fotovoltaica | H12: =CAPEX!K3 -> 54 MW + 34.08% BESS | I12: =CAPEX!M3 -> 46478 | J12: =CAPEX!N3 -> 47057 | K12: =CAPEX!AH3 -> 1 | L12: =CAPEX!AI3 -> 0 | M12: =CAPEX!AJ3 -> 1 | N12: =CAPEX!AK3 -> 0.5 | O12: =CAPEX!AL3 -> 0.5 | P12: =CAPEX!AM3 -> 1 | Q12: =CAPEX!AN3 -> 0 | R12: =CAPEX!AO3 -> 0.9 | ... AB12: =CAPEX!AY3 -> 0.9 | AD12: =CAPEX!AE3 -> 0.8 | AE12: =CAPEX!AF3 -> 0.555 | AG12: =CAPEX!AG3 -> 0.751
B13: 3 | C13: =CAPEX!F4 -> Actis | D13: =CAPEX!E4 -> Viento de Bella Unión | E13: =CAPEX!AD4 -> Arteaga | F13: =CAPEX!AC4 -> Coahuila | G13: =CAPEX!G4 -> Fotovoltaica | H13: =CAPEX!K4 -> 120 MW + 34.08% BESS | I13: =CAPEX!M4 -> 46507 | J13: =CAPEX!N4 -> 47057 | K13: =CAPEX!AH4 -> 0.5 | L13: =CAPEX!AI4 -> 0.95 | M13: =CAPEX!AJ4 -> 1 | N13: =CAPEX!AK4 -> 0.5 | O13: =CAPEX!AL4 -> 0.5 | P13: =CAPEX!AM4 -> 1 | Q13: =CAPEX!AN4 -> 1 | R13: =CAPEX!AO4 -> 0.5 | ... AB13: =CAPEX!AY4 -> 0 | AD13: =CAPEX!AE4 -> 0.6 | AE13: =CAPEX!AF4 -> 0.645 | AG13: =CAPEX!AG4 -> 0.609
B14: 4 | C14: =CAPEX!F5 -> Alten | D14: =CAPEX!E5 -> Global Solar 3 Campeche | E14: =CAPEX!AD5 -> El Carmen | F14: =CAPEX!AC5 -> Campeche | G14: =CAPEX!G5 -> Fotovoltaica | H14: =CAPEX!K5 -> 125 MW + 30.00% BESS | I14: =CAPEX!M5 -> 46388 | J14: =CAPEX!N5 -> 46935 | K14: =CAPEX!AH5 -> 1 | L14: =CAPEX!AI5 -> 0 | M14: =CAPEX!AJ5 -> 1 | N14: =CAPEX!AK5 -> 0.9 | O14: =CAPEX!AL5 -> 0.9 | P14: =CAPEX!AM5 -> 0.8 | Q14: =CAPEX!AN5 -> 1 | R14: =CAPEX!AO5 -> 1 | ... AB14: =CAPEX!AY5 -> 0.8 | AD14: =CAPEX!AE5 -> 0.875 | AE14: =CAPEX!AF5 -> 0.8 | AG14: =CAPEX!AG5 -> 0.86
B15: 5 | C15: =CAPEX!F6 -> Atlántica | D15: =CAPEX!E6 -> Dalia 3 (Castamay) | E15: =CAPEX!AD6 -> Castamay | F15: =CAPEX!AC6 -> Campeche | G15: =CAPEX!G6 -> Fotovoltaica | H15: =CAPEX!K6 -> 100 MW + 30% BESS | I15: =CAPEX!M6 -> 46447 | J15: =CAPEX!N6 -> 47118 | K15: =CAPEX!AH6 -> 0.9 | L15: =CAPEX!AI6 -> 0.5 | M15: =CAPEX!AJ6 -> 1 | N15: =CAPEX!AK6 -> 0.8 | O15: =CAPEX!AL6 -> 0.6 | P15: =CAPEX!AM6 -> 0.5 | Q15: =CAPEX!AN6 -> 0 | R15: =CAPEX!AO6 -> 0.8 | ... AB15: =CAPEX!AY6 -> 1 | AD15: =CAPEX!AE6 -> 0.79 | AE15: =CAPEX!AF6 -> 0.535 | AG15: =CAPEX!AG6 -> 0.739
B16: 6 | C16: =CAPEX!F7 -> Atlántica | D16: =CAPEX!E7 -> Fresnillo (PV Atocha) | E16: =CAPEX!AD7 -> Fresnillo | F16: =CAPEX!AC7 -> Zacatecas | G16: =CAPEX!G7 -> Fotovoltaica | H16: =CAPEX!K7 -> 100 MW + 30% BESS | I16: =CAPEX!M7 -> 46447 | J16: =CAPEX!N7 -> 47118 | K16: =CAPEX!AH7 -> 0.7 | L16: =CAPEX!AI7 -> 0.7 | M16: =CAPEX!AJ7 -> 1 | N16: =CAPEX!AK7 -> 0.7 | O16: =CAPEX!AL7 -> 0 | P16: =CAPEX!AM7 -> 0 | Q16: =CAPEX!AN7 -> 0 | R16: =CAPEX!AO7 -> 0.7 | ... AB16: =CAPEX!AY7 -> 0 | AD16: =CAPEX!AE7 -> 0.625 | AE16: =CAPEX!AF7 -> 0.41 | AG16: =CAPEX!AG7 -> 0.582
B17: 7 | C17: =CAPEX!F8 -> Atlas Renewable Energy | D17: =CAPEX!E8 -> Concepción Mendizábal M. - Fase I | E17: =CAPEX!AD8 -> Nava | F17: =CAPEX!AC8 -> Coahuila | G17: =CAPEX!G8 -> Fotovoltaica | H17: =CAPEX!K8 -> 339 MW + 30.00% BESS | I17: =CAPEX!M8 -> 46478 | J17: =CAPEX!N8 -> 47209 | K17: =CAPEX!AH8 -> 1 | L17: =CAPEX!AI8 -> 1 | M17: =CAPEX!AJ8 -> 0.8 | N17: =CAPEX!AK8 -> 0.9 | O17: =CAPEX!AL8 -> 0.9 | P17: =CAPEX!AM8 -> 1 | Q17: =CAPEX!AN8 -> 1 | R17: =CAPEX!AO8 -> 1 | ... AB17: =CAPEX!AY8 -> 0 | AD17: =CAPEX!AE8 -> 0.8375 | AE17: =CAPEX!AF8 -> 0.8375 | AG17: =CAPEX!AG8 -> 0.8375
B18: 8 | C18: =CAPEX!F9 -> Atlas Renewable Energy | D18: =CAPEX!E9 -> Concepción Mendizábal M. - Fase II | E18: =CAPEX!AD9 -> Nava | F18: =CAPEX!AC9 -> Coahuila | G18: =CAPEX!G9 -> Fotovoltaica | H18: =CAPEX!K9 -> 180 MW + 30.00% BESS | I18: =CAPEX!M9 -> 46478 | J18: =CAPEX!N9 -> 47209 | K18: =CAPEX!AH9 -> 1 | L18: =CAPEX!AI9 -> 1 | M18: =CAPEX!AJ9 -> 0.8 | N18: =CAPEX!AK9 -> 0.9 | O18: =CAPEX!AL9 -> 0.9 | P18: =CAPEX!AM9 -> 1 | Q18: =CAPEX!AN9 -> 1 | R18: =CAPEX!AO9 -> 1 | ... AB18: =CAPEX!AY9 -> 0 | AD18: =CAPEX!AE9 -> 0.8375 | AE18: =CAPEX!AF9 -> 0.8375 | AG18: =CAPEX!AG9 -> 0.8375
B19: 9 | C19: =CAPEX!F10 -> Atlas Renewable Energy | D19: =CAPEX!E10 -> Concepción Mendizábal M. - Fase III | E19: =CAPEX!AD10 -> Nava | F19: =CAPEX!AC10 -> Coahuila | G19: =CAPEX!G10 -> Fotovoltaica | H19: =CAPEX!K10 -> 339 MW + 30.00% BESS | I19: =CAPEX!M10 -> 46478 | J19: =CAPEX!N10 -> 47209 | K19: =CAPEX!AH10 -> 1 | L19: =CAPEX!AI10 -> 1 | M19: =CAPEX!AJ10 -> 0.8 | N19: =CAPEX!AK10 -> 0.9 | O19: =CAPEX!AL10 -> 0.9 | P19: =CAPEX!AM10 -> 0.9 | Q19: =CAPEX!AN10 -> 0.9 | R19: =CAPEX!AO10 -> 1 | ... AB19: =CAPEX!AY10 -> 0 | AD19: =CAPEX!AE10 -> 0.8275 | AE19: =CAPEX!AF10 -> 0.8275 | AG19: =CAPEX!AG10 -> 0.8275
B20: 10 | C20: =CAPEX!F11 -> CSQB Energy | D20: =CAPEX!E11 -> Cimarrón Solar (**) | E20: =CAPEX!AD11 -> Hermosillo | F20: =CAPEX!AC11 -> Sonora | G20: =CAPEX!G11 -> Fotovoltaica | H20: =CAPEX!K11 -> 300 MW + 30% BESS | I20: =CAPEX!M11 -> 46507 | J20: =CAPEX!N11 -> 47238 | K20: =CAPEX!AH11 -> 0.5 | L20: =CAPEX!AI11 -> 1 | M20: =CAPEX!AJ11 -> 0 | N20: =CAPEX!AK11 -> 0 | O20: =CAPEX!AL11 -> 0 | P20: =CAPEX!AM11 -> 0 | Q20: =CAPEX!AN11 -> 0 | R20: =CAPEX!AO11 -> 0.5 | ... AB20: =CAPEX!AY11 -> 0 | AD20: =CAPEX!AE11 -> 0.35 | AE20: =CAPEX!AF11 -> 0.4 | AG20: =CAPEX!AG11 -> 0.36
B21: 11 | C21: =CAPEX!F12 -> CSQB Energy | D21: =CAPEX!E12 -> La Poza Solar (**) | E21: =CAPEX!AD12 -> Hermosillo | F21: =CAPEX!AC12 -> Sonora | G21: =CAPEX!G12 -> Fotovoltaica | H21: =CAPEX!K12 -> 300 MW + 30% BESS | I21: =CAPEX!M12 -> 46507 | J21: =CAPEX!N12 -> 47238 | K21: =CAPEX!AH12 -> 0.5 | L21: =CAPEX!AI12 -> 0.5 | M21: =CAPEX!AJ12 -> 0 | N21: =CAPEX!AK12 -> 0 | O21: =CAPEX!AL12 -> 0 | P21: =CAPEX!AM12 -> 0 | Q21: =CAPEX!AN12 -> 0 | R21: =CAPEX!AO12 -> 0.5 | ... AB21: =CAPEX!AY12 -> 0.5 | AD21: =CAPEX!AE12 -> 0.35 | AE21: =CAPEX!AF12 -> 0.35 | AG21: =CAPEX!AG12 -> 0.35
B22: 12 | C22: =CAPEX!F13 -> CSQB Energy | D22: =CAPEX!E13 -> Sunora (**) | E22: =CAPEX!AD13 -> Hermosillo | F22: =CAPEX!AC13 -> Sonora | G22: =CAPEX!G13 -> Fotovoltaica | H22: =CAPEX!K13 -> 300 MW + 30% BESS | I22: =CAPEX!M13 -> 46507 | J22: =CAPEX!N13 -> 47238 | K22: =CAPEX!AH13 -> 0.5 | L22: =CAPEX!AI13 -> 1 | M22: =CAPEX!AJ13 -> 0 | N22: =CAPEX!AK13 -> 0.6 | O22: =CAPEX!AL13 -> 0.6 | P22: =CAPEX!AM13 -> 0 | Q22: =CAPEX!AN13 -> 0 | R22: =CAPEX!AO13 -> 0.6 | ... AB22: =CAPEX!AY13 -> 0.5 | AD22: =CAPEX!AE13 -> 0.49 | AE22: =CAPEX!AF13 -> 0.54 | AG22: =CAPEX!AG13 -> 0.5
... B50: 40 | C50: =CAPEX!F41 -> Thermion | D50: =CAPEX!E41 -> Sol de Sonora 70 | E50: =CAPEX!AD41 -> Hermosillo | F50: =CAPEX!AC41 -> Sonora | G50: =CAPEX!G41 -> Fotovoltaica | H50: =CAPEX!K41 -> 70 MW + 31.43% BESS | I50: =CAPEX!M41 -> 46357 | J50: =CAPEX!N41 -> 46844 | K50: =CAPEX!AH41 -> 1 | L50: =CAPEX!AI41 -> 1 | M50: =CAPEX!AJ41 -> 1 | N50: =CAPEX!AK41 -> 0.8 | O50: =CAPEX!AL41 -> 0.8 | P50: =CAPEX!AM41 -> 0.8 | Q50: =CAPEX!AN41 -> 0.8 | R50: =CAPEX!AO41 -> 0.8 | ... AB50: =CAPEX!AY41 -> 0.5 | AD50: =CAPEX!AE41 -> 0.82 | AE50: =CAPEX!AF41 -> 0.82 | AG50: =CAPEX!AG41 -> 0.82
K51: Ponderan | M51: Pondera | N51: Ponderan | R51: Ponderan | T51: Pondera | U51: Ponderan | W51: Ponderan | Y51: Ponderan | AA51: Ponderan | AD51: Pondera | AE51: Pondera
K52: 0.1 | M52: 0.1 | N52: 0.2 | P52: 0.1 | R52: 0.2 | T52: 0.1 | U52: 0.05 | W52: 0.05 | Y52: 0.05 | AA52: 0.05 | AD52: 0.8 | AE52: 0.2
D54: (*) | E54: Indica Proyecto que se va a segunda ronda de Proyectos Mixtos
D55: (**) | E55: Indica Proyecto que no puede ser ingresado al SEN sin que entren obras de refuerzo que no son responsabilidad del Proyecto, es decir, por un tercero; según CENACE
AD95: 0
AD96: 1

Sheet CAPEX
